Workbook

Sheet CBES
A1: CAJA BANCARIA ESTATAL DE SALUD | M1: Nº PATRONAL: | O1: 11-730-0001
B2: COTIZACIONES
A3: CAJA BANCARIA ESTATAL DE SALUD | Q3: SOLO SE REEMBOLSA 30 DIAS EN TODOS LOS TIPO DE BAJA
C4: ENFERMEDAD COMUN | Q4: SOLO SE REEMBOLSA DEL MES QUE CORRESPONDA
A5: N° | B5: NOMBRE | C5: BAJA MEDICA | E5: dia | F5: CORRESPONDIENTE AL MES | H5: DIA | I5: DIA- 3 DIAS | J5: TOTAL GANADO | K5: TOTAL DIA | L5: DIAS CBES | M5: TOTAL | N5: TOTAL (75%) | O5: OBSERVACION | P5: 3 | Q5: IGUAL QUE LOS APORTES PARA REALIZAR LA PRESENTACION DE SOLICITUD DE REEBOLSO
C6: Empiezo | D6: Termino | F6: DE | G6: A
F7: 0 | G7: 0 | H7: =G7-F7+1 -> 1 | I7: =H7-3 -> -2 | J7: 0 | K7: =J7/30 -> 0 | M7: =K7*L7 -> 0 | N7: =M7*0.75 -> 0
A8: 1 | B8: LOZA MUJICA POLET LUCIA | E8: =+D8-C8+1 -> 1 | F8: 45674 | G8: 45678 | H8: =+G8-F8+1 -> 5 | I8: =+H8-3 -> 2 | J8: 3102 | K8: =J8/22 -> 141 | L8: =+I8 -> 2 | M8: =K8*L8 -> 282 | N8: =M8*0.75 -> 211.5
A9: 2 | B9: LAIME LAIME ROSMERY | C9: 45684 | D9: 45689 | E9: =+D9-C9+1 -> 6 | F9: 45658 | G9: 45677 | H9: =+G9-F9+1 -> 20 | I9: =+H9-3 -> 17 | J9: 5320 | K9: =J9/30 -> 177.33333 | L9: 0 | M9: =K9*L9 -> 0 | N9: =M9*0.75 -> 0 | O9: SDP | P9: HORA
E10: =+D10-C10+1 -> 1 | H10: =+G10-F10+1 -> 1 | I10: =H10-3 -> -2 | K10: =J10/30 -> 0 | M10: =K10*L10 -> 0 | N10: =M10*0.75 -> 0
N11: =SUM(N7:N10) -> 211.5
C12: BAJAS POR MATERNIDAD
P13: 1
A14: N° | B14: NOMBRE | C14: BAJA MEDICA | F14: CORRESPONDIENTE AL MES | H14: DIA | J14: TOTAL GANADO | K14: TOTAL DIA | L14: DIAS CBES | M14: TOTAL | N14: TOTAL (90%) | O14: OBSERVACION
C15: Empiezo | D15: Termino | F15: DE | G15: A
A16: 1 | B16: PAUCARA APAZA LIBIA SANDRA | C16: 45659 | D16: 45703 | E16: =+D16-C16+1 -> 45 | F16: 45659 | G16: 45687 | H16: =+G16-F16+1 -> 29 | I16: =+H16 -> 29 | J16: 8194 | K16: =J16/30 -> 273.13333 | L16: =+I16 -> 29 | M16: =K16*L16 -> 7920.8667 | N16: =M16*0.9 -> 7128.78
A17: 2 | B17: CONDE MEJIA MARIELA YOSELYN 95-6011 CMM | C17: 45672 | D17: 45716 | E17: =+D17-C17+1 -> 45 | F17: 45672 | G17: 45687 | H17: =+G17-F17+1 -> 16 | I17: =+H17 -> 16 | J17: 4230 | K17: =J17/30 -> 141 | L17: =+I17 -> 16 | M17: =K17*L17 -> 2256 | N17: =M17*0.9 -> 2030.4
E18: =+D18-C18+1 -> 1 | H18: =+G18-F18+1 -> 1 | I18: =+H18 -> 1 | K18: =J18/30 -> 0 | M18: =K18*L18 -> 0 | N18: =M18*0.9 -> 0
N19: =SUM(N16:N18) -> 9159.18
C20: ACCIDENTE DE TRABAJO
A22: N° | B22: NOMBRE | C22: BAJA MEDICA | F22: LA PAZ | H22: DIA | J22: TOTAL GANADO | K22: TOTAL DIA | L22: DIAS CBES | M22: TOTAL | N22: TOTAL (90%) | O22: OBSERVACION | P22: 2
C23: Empiezo | D23: Termino | F23: DE | G23: A
E24: =D24-C24+1 -> 1 | F24: 0 | G24: 0 | H24: =G24-F24+1 -> 1 | J24: 0 | K24: =J24/30 -> 0 | M24: =K24*L24 -> 0 | N24: =M24*0.9 -> 0
A25: 1 | B25: SUCOJAYO NAO HEIDY 92-5101 SNH | C25: 45688 | D25: 45688 | F25: 45687 | G25: 45687 | H25: =+G25-F25+1 -> 1 | I25: =+H25 -> 1 | J25: 4230 | K25: =J25/30 -> 141 | L25: 0 | M25: =K25*L25 -> 0 | N25: =M25*0.9 -> 0 | O25: CALCULO COMERCIAL
H26: =+G26-F26+1 -> 1 | I26: =+H26 -> 1 | K26: =J26/30 -> 0 | M26: =K26*L26 -> 0 | N26: =M26*0.9 -> 0
N27: =SUM(N24:N26) -> 0
K29: TOTAL REEMB | N29: =N11+N19+N27 -> 9370.68

Sheet BCB
A1: CAJA BANCARIA ESTATAL DE SALUD | N1: Nº PATRONAL: | O1: 11-710-0001
A2: COTIZACIONES
A3: BANCO CENTRAL DE BOLIVIA
C4: ENFERMEDAD COMUN
A5: N° | B5: NOMBRE | C5: BAJA MEDICA | E5: dia | F5: CORRESPONDIENTE AL MES | H5: DIA | I5: dia -3 | J5: TOTAL GANADO | K5: TOTAL DIA | L5: DIAS CBES | M5: TOTAL | N5: TOTAL (75%) | O5: OBSERVACION
C6: Empiezo | D6: Termino | F6: DE | G6: A
A7: 3 | B7: ZENTENO SILES JOSE FERNANDO | C7: 45664 | D7: 45688 | E7: =D7-C7+1 -> 25 | F7: 45664 | G7: 45687 | H7: =G7-F7+1 -> 24 | I7: =H7-3 -> 21 | J7: 13489 | K7: =J7/30 -> 449.63333 | L7: =+I7 -> 21 | M7: =K7*L7 -> 9442.3 | N7: =M7*0.75 -> 7081.725
A8: 4 | B8: DAVALOS TORREZ SILVIA | C8: 45649 | D8: 45664 | E8: =D8-C8+1 -> 16 | F8: 45658 | G8: 45664 | H8: =G8-F8+1 -> 7 | I8: =H8-3 -> 4 | J8: 15560 | K8: =J8/30 -> 518.66667 | L8: 7 | M8: =K8*L8 -> 3630.6667 | N8: =M8*0.75 -> 2723
N9: =SUM(N7:N8) -> 9804.725
C10: BAJAS POR MATERNIDAD
A12: N° | B12: NOMBRE | C12: BAJA MEDICA | F12: LA PAZ | H12: DIA | J12: TOTAL GANADO | K12: TOTAL DIA | L12: DIAS CBES | M12: TOTAL | N12: TOTAL (90%) | O12: OBSERVACION
C13: Empiezo | D13: Termino | F13: DE | G13: A
E14: =D14-C14+1 -> 1 | F14: 0 | G14: 0 | H14: =G14-F14+1 -> 1 | J14: 0 | K14: =J14/30 -> 0 | M14: =K14*L14 -> 0 | N14: =M14*0.9 -> 0
A15: 1 | B15: MONTAÑO HURTADO JHOSELINE | C15: 45639 | D15: 45728 | E15: =+D15-C15+1 -> 90 | F15: 45658 | G15: 45687 | H15: =G15-F15+1 -> 30 | J15: 8268 | K15: =J15/30 -> 275.6 | L15: =+H15 -> 30 | M15: =+L15*K15 -> 8268 | N15: =+M15*0.9 -> 7441.2
E16: =+D16-C16+1 -> 1 | H16: =G16-F16+1 -> 1 | K16: =J16/30 -> 0 | M16: =+L16*K16 -> 0 | N16: =+M16*0.9 -> 0
N17: =SUM(N14:N16) -> 7441.2
C18: ACCIDENTE DE TRABAJO
A20: N° | B20: NOMBRE | C20: BAJA MEDICA | F20: LA PAZ | H20: DIA | J20: TOTAL GANADO | K20: TOTAL DIA | L20: DIAS CBES | M20: TOTAL | N20: TOTAL (90%) | O20: OBSERVACION
C21: Empiezo | D21: Termino | F21: DE | G21: A
E22: =D22-C22+1 -> 1 | F22: 0 | G22: 0 | H22: =G22-F22+1 -> 1 | J22: 0 | K22: =J22/30 -> 0 | M22: =K22*L22 -> 0 | N22: =M22*0.9 -> 0
A23: 1 | B23: ZAPANA CALDERON HILDA Y. | E23: =D23-C23+1 -> 1 | F23: 45664 | G23: 45684 | H23: =G23-F23+1 -> 21 | J23: 8718 | K23: =J23/30 -> 290.6 | L23: =+H23 -> 21 | M23: =K23*L23 -> 6102.6 | N23: =M23*0.9 -> 5492.34
A24: 2 | B24: ASCARRUNZ PALZA CINTHIA Y. | E24: =D24-C24+1 -> 1 | F24: 45671 | G24: 45672 | H24: =G24-F24+1 -> 2 | J24: 15560 | K24: =J24/30 -> 518.66667 | L24: =+H24 -> 2 | M24: =K24*L24 -> 1037.3333 | N24: =M24*0.9 -> 933.6
E25: =D25-C25+1 -> 1 | H25: =G25-F25+1 -> 1 | K25: =J25/30 -> 0 | M25: =K25*L25 -> 0 | N25: =M25*0.9 -> 0
N26: =SUM(N22:N25) -> 6425.94
K28: TOTAL REEMB | N28: =N9+N17+N26 -> 23671.865

Sheet ASFI
A1: CAJA BANCARIA ESTATAL DE SALUD | M1: Nº PATRONAL : | O1: 11-710-0005
A2: COTIZACIONES
A3: AUTORIDAD DE SUPERVISION DEL SISTEMA FINANCIERO
C4: ENFERMEDAD COMUN
A5: N° | B5: NOMBRE | C5: BAJA MEDICA | F5: LA PAZ | H5: DIA | J5: TOTAL GANADO | K5: TOTAL DIA | L5: DIAS CBES | M5: TOTAL | N5: TOTAL (75%) | O5: OBSERVACION
C6: Empiezo | D6: Termino | F6: DE | G6: A
F7: 0 | G7: 0 | H7: =G7-F7+1 -> 1 | I7: =H7-3 -> -2 | J7: 0 | K7: =J7/30 -> 0 | M7: =K7*L7 -> 0 | N7: =M7*0.75 -> 0
A8: 1 | B8: AGUILAR BARRIGA DIEGO ADRIAN | C8: 45650 | D8: 45660 | E8: =+D8-C8+1 -> 11 | F8: 45658 | G8: 45660 | H8: =G8-F8+1 -> 3 | I8: =H8-3 -> 0 | J8: 9553 | K8: =J8/30 -> 318.43333 | L8: 3 | M8: =K8*L8 -> 955.3 | N8: =M8*0.75-0.01 -> 716.465
A9: 2 | B9: ARCE CUELLAR MARIA SELVA | C9: 45650 | D9: 45691 | E9: =+D9-C9+1 -> 42 | F9: 45658 | G9: 45687 | H9: =G9-F9+1 -> 30 | I9: =H9-3 -> 27 | J9: 20043 | K9: =J9/30 -> 668.1 | L9: 30 | M9: =K9*L9 -> 20043 | N9: =M9*0.75 -> 15032.25
A10: 3 | B10: BELLIDO QUINTANILLA HUMBERTO MARTIN | C10: 45647 | D10: 45688 | E10: =+D10-C10+1 -> 42 | F10: 45658 | G10: 45687 | H10: =G10-F10+1 -> 30 | I10: =H10-3 -> 27 | J10: 18262 | K10: =J10/30 -> 608.73333 | L10: 30 | M10: =K10*L10 -> 18262 | N10: =M10*0.75-0.07 -> 13696.43
A11: 4 | B11: MEDRANO ROCHA ANGELA ALEJANDRA | C11: 45672 | D11: 45691 | E11: =+D11-C11+1 -> 20 | F11: 45672 | G11: 45687 | H11: =G11-F11+1 -> 16 | I11: =H11-3 -> 13 | J11: 20745 | K11: =J11/30 -> 691.5 | L11: =+I11 -> 13 | M11: =K11*L11 -> 8989.5 | N11: =M11*0.75 -> 6742.125
N12: =SUM(N7:N11)+0.01 -> 36187.28
F13: BAJAS POR MATERNIDAD
A15: N° | B15: NOMBRE | C15: BAJA MEDICA | E15: dia | F15: LA PAZ | H15: DIA | J15: TOTAL GANADO | K15: TOTAL DIA | L15: DIAS CBES | M15: TOTAL | N15: TOTAL (90%) | O15: OBSERVACION
C16: Empiezo | D16: Termino | F16: DE | G16: A
E17: =D17-C17+1 -> 1 | H17: =G17-F17+1 -> 1 | K17: =J17/30 -> 0 | M17: =K17*L17 -> 0 | N17: =M17*0.9 -> 0
A18: 1 | B18: OCHOA CHOQUE MARIA ROSARIO | C18: 45603 | D18: 45692 | E18: =D18-C18+1 -> 90 | F18: 45658 | G18: 45687 | H18: =G18-F18+1 -> 30 | J18: 14138 | K18: =J18/30 -> 471.26667 | L18: =+H18 -> 30 | M18: =K18*L18 -> 14138 | N18: =M18*0.9+0.09 -> 12724.29
N19: =SUM(N17:N18) -> 12724.29
F20: ACCIDENTE DE TRABAJO
A22: N° | B22: NOMBRE | C22: BAJA MEDICA | F22: LA PAZ | H22: DIA | J22: TOTAL GANADO | K22: TOTAL DIA | L22: DIAS CBES | M22: TOTAL | N22: TOTAL (90%) | O22: OBSERVACION
C23: Empiezo | D23: Termino | F23: DE | G23: A
H24: =G24-F24+1 -> 1 | J24: 0 | K24: =J24/30 -> 0 | M24: =K24*L24 -> 0 | N24: =M24*0.9 -> 0
H25: =G25-F25+1 -> 1 | J25: 0 | K25: =J25/30 -> 0 | M25: =K25*L25 -> 0 | N25: =M25*0.9 -> 0
N26: =SUM(N24:N25) -> 0
K28: TOTAL REEMBOLSO | N28: =N26+N19+N12 -> 48911.57

Sheet UIF
A1: CAJA BANCARIA ESTATAL DE SALUD
A2: COTIZACIONES | N2: Nº. PATRONAL: | O2: 11-710-0008
A3: UNIDAD DE INVESTIGACIONES FINANCIERAS
C4: ENFERMEDAD COMUN
A5: N° | B5: NOMBRE | C5: BAJA MEDICA | F5: LA PAZ | H5: DIA | J5: TOTAL GANADO | K5: TOTAL DIA | L5: DIAS CBES | M5: TOTAL | N5: TOTAL (75%) | O5: OBSERVACION
C6: Empiezo | D6: Termino | F6: DE | G6: A
C7: 0 | D7: 0 | F7: 0 | G7: 0 | H7: =G7-F7+1 -> 1 | I7: =H7-3 -> -2 | J7: 0 | K7: =J7/30 -> 0 | M7: =K7*L7 -> 0 | N7: =M7*0.75 -> 0
A8: 1 | B8: RENJIFO VALDIVIA GILKA CLAUDIA | C8: 45994 | D8: 45690 | E8: =D8-C8+1 -> -303 | F8: 45658 | G8: 45687 | H8: =G8-F8+1 -> 30 | I8: =H8-3 -> 27 | J8: 10731 | K8: =J8/30 -> 357.7 | L8: 30 | M8: =K8*L8 -> 10731 | N8: =M8*0.75 -> 8048.25
A9: 2 | B9: QUISPE MAMANI NINFA RUTH | C9: 45657 | D9: 45666 | E9: =D9-C9+1 -> 10 | F9: 45658 | G9: 45666 | H9: =G9-F9+1 -> 9 | I9: =H9-3 -> 6 | J9: 11853 | K9: =J9/30 -> 395.1 | L9: =+I9 -> 6 | M9: =K9*L9 -> 2370.6 | N9: =M9*0.75 -> 1777.95
A10: 3 | B10: HUARINA VILLANUEVA VERONICA | C10: 45678 | D10: 45685 | E10: =D10-C10+1 -> 8 | F10: 45679 | G10: 45685 | H10: =G10-F10+1 -> 7 | I10: =H10-3 -> 4 | J10: 11853 | K10: =J10/30 -> 395.1 | L10: =+I10 -> 4 | M10: =K10*L10 -> 1580.4 | N10: =M10*0.75 -> 1185.3
N11: =SUM(N7:N10) -> 11011.5
C12: BAJAS POR MATERNIDAD
A14: N° | B14: NOMBRE | C14: BAJA MEDICA | E14: DIA | F14: LA PAZ | H14: DIA | J14: TOTAL GANADO | K14: TOTAL DIA | L14: DIAS CBES | M14: TOTAL | N14: TOTAL (90%) | O14: OBSERVACION
C15: Empiezo | D15: Termino | F15: DE | G15: A
C16: 0 | D16: 0 | E16: =D16-C16+1 -> 1 | F16: 0 | G16: 0 | H16: =G16-F16+1 -> 1 | J16: 0 | K16: =J16/30 -> 0 | M16: =K16*L16 -> 0 | N16: =M16*0.9 -> 0
E17: =D17-C17+1 -> 1 | H17: =G17-F17+1 -> 1 | I17: 30 | K17: =J17/30 -> 0 | M17: =K17*L17 -> 0 | N17: =M17*0.9 -> 0
E18: =D18-C18+1 -> 1 | H18: =G18-F18+1 -> 1 | K18: =J18/30 -> 0 | M18: =K18*L18 -> 0 | N18: =M18*0.9 -> 0
N19: =SUM(N16:N18) -> 0
C20: ACCIDENTE DE TRABAJO
A22: N° | B22: NOMBRE | C22: BAJA MEDICA | F22: LA PAZ | H22: DIA | J22: TOTAL GANADO | K22: TOTAL DIA | L22: DIAS CBES | M22: TOTAL | N22: TOTAL (90%) | O22: OBSERVACION
C23: Empiezo | D23: Termino | F23: DE | G23: A
C24: 0 | D24: 0 | H24: =G24-F24+1 -> 1 | J24: 0 | K24: =J24/30 -> 0 | L24: 0 | M24: =K24*L24 -> 0 | N24: =M24*0.9 -> 0
H25: =G25-F25+1 -> 1 | J25: 0 | K25: =J25/30 -> 0 | L25: 0 | M25: =K25*L25 -> 0 | N25: =M25*0.9 -> 0
H26: =G26-F26+1 -> 1 | J26: 0 | K26: =J26/30 -> 0 | L26: 0 | M26: =K26*L26 -> 0 | N26: =M26*0.9 -> 0
N27: =SUM(N24:N26) -> 0
K29: TOTAL REEMB | N29: =N11+N19+N27 -> 11011.5

Sheet FC-BCB
B1: CAJA BANCARIA ESTATAL DE SALUD
B2: COTIZACIONES | N2: Nº. PATRONAL : | O2: 11-929-0001
A3: FUNDACION CULTURAL - BCB
C4: ENFERMEDAD COMUN
A5: N° | B5: NOMBRE | C5: BAJA MEDICA | E5: DIA | F5: LA PAZ | H5: DIA | J5: TOTAL GANADO | K5: TOTAL DIA | L5: DIAS CBES | M5: TOTAL | N5: TOTAL (75%) | O5: OBSERVACION
C6: Empiezo | D6: Termino | F6: DE | G6: A
C7: 0 | D7: 0 | E7: =D7-C7+1 -> 1 | F7: 0 | G7: 0 | H7: =G7-F7+1 -> 1 | I7: =H7-3 -> -2 | J7: 0 | K7: =J7/30 -> 0 | M7: =K7*L7 -> 0 | N7: =M7*0.75 -> 0
A8: 1 | B8: SEMPERTEGUI ALVAREZ MARIO HECTOR | C8: 45649 | D8: 45690 | E8: =D8-C8+1 -> 42 | F8: 45658 | G8: 45687 | H8: =G8-F8+1 -> 30 | I8: =H8-3 -> 27 | J8: 9003 | K8: =J8/30 -> 300.1 | L8: 30 | M8: =K8*L8 -> 9003 | N8: =M8*0.75 -> 6752.25
E9: =D9-C9+1 -> 1 | H9: =G9-F9+1 -> 1 | I9: =H9-3 -> -2 | K9: =J9/30 -> 0 | M9: =K9*L9 -> 0 | N9: =M9*0.75 -> 0
E10: =D10-C10+1 -> 1 | H10: =G10-F10+1 -> 1 | I10: =H10-3 -> -2 | K10: =J10/30 -> 0 | M10: =K10*L10 -> 0 | N10: =M10*0.75 -> 0
N11: =SUM(N7:N10) -> 6752.25
C12: BAJAS POR MATERNIDAD
A14: N° | B14: NOMBRE | C14: BAJA MEDICA | E14: DIA | F14: LA PAZ | H14: DIA | J14: TOTAL GANADO | K14: TOTAL DIA | L14: DIAS CBES | M14: TOTAL | N14: TOTAL (90%) | O14: OBSERVACION
C15: Empiezo | D15: Termino | F15: DE | G15: A
C16: 0 | D16: 0 | E16: =D16-C16+1 -> 1 | F16: 0 | G16: 0 | H16: =G16-F16+1 -> 1 | J16: 0 | K16: =J16/30 -> 0 | M16: =K16*L16 -> 0 | N16: =M16*0.9 -> 0
A17: 1 | E17: =D17-C17+1 -> 1 | H17: =G17-F17+1 -> 1 | K17: =J17/30 -> 0 | M17: =K17*L17 -> 0 | N17: =M17*0.9 -> 0
E18: =D18-C18+1 -> 1 | H18: =G18-F18+1 -> 1 | J18: 0 | K18: =J18/30 -> 0 | M18: =K18*L18 -> 0 | N18: =M18*0.9 -> 0
N19: =SUM(N16:N18) -> 0
C20: ACCIDENTE DE TRABAJO
A22: N° | B22: NOMBRE | C22: BAJA MEDICA | E22: DIA | F22: LA PAZ | H22: DIA | J22: TOTAL GANADO | K22: TOTAL DIA | L22: DIAS CBES | M22: TOTAL | N22: TOTAL (90%) | O22: OBSERVACION
C23: Empiezo | D23: Termino | F23: DE | G23: A
C24: 0 | D24: 0 | E24: =D24-C24+1 -> 1 | H24: =G24-F24+1 -> 1 | J24: 0 | K24: =J24/30 -> 0 | M24: =K24*L24 -> 0 | N24: =M24*0.9 -> 0
E25: =D25-C25+1 -> 1 | H25: =G25-F25+1 -> 1 | J25: 0 | K25: =J25/30 -> 0 | M25: =K25*L25 -> 0 | N25: =M25*0.9 -> 0
E26: =D26-C26+1 -> 1 | H26: =G26-F26+1 -> 1 | J26: 0 | K26: =J26/30 -> 0 | M26: =K26*L26 -> 0 | N26: =M26*0.9 -> 0
N27: =SUM(N24:N26) -> 0
K29: TOTAL REEMB | N29: =N27+N19+N11 -> 6752.25

Sheet MNA
B1: CAJA BANCARIA ESTATAL DE SALUD
B2: COTIZACIONES | M2: Nº. PATRONAL : | O2: 11-929-0001
A4: FUNDACION CULTURAL - MNA
C5: ENFERMEDAD COMUN
A6: N° | B6: NOMBRE | C6: BAJA MEDICA | E6: DIA | F6: LA PAZ | H6: DIA | J6: TOTAL GANADO | K6: TOTAL DIA | L6: DIAS CBES | M6: TOTAL | N6: TOTAL (75%) | O6: OBSERVACION
C7: Empiezo | D7: Termino | F7: DE | G7: A
C8: 0 | D8: 0 | E8: =D8-C8+1 -> 1 | F8: 0 | G8: 0 | H8: =G8-F8+1 -> 1 | I8: =H8-3 -> -2 | J8: 0 | K8: =J8/30 -> 0 | L8: 0 | M8: =K8*L8 -> 0 | N8: =M8*0.75 -> 0
A9: 1 | B9: ARAUZ MARAÑON CLAUDIA MARCELA | C9: 45674 | D9: 45701 | E9: =D9-C9+1 -> 28 | F9: 45674 | G9: 45687 | H9: =G9-F9+1 -> 14 | I9: =H9-3 -> 11 | J9: 9461 | K9: =J9/30 -> 315.36667 | L9: =+I9 -> 11 | M9: =K9*L9 -> 3469.0333 | N9: =M9*0.75 -> 2601.775
E10: =D10-C10+1 -> 1 | H10: =G10-F10+1 -> 1 | I10: =H10-3 -> -2 | K10: =J10/30 -> 0 | M10: =K10*L10 -> 0 | N10: =M10*0.75 -> 0
E11: =D11-C11+1 -> 1 | H11: =G11-F11+1 -> 1 | I11: =H11-3 -> -2 | K11: =J11/30 -> 0 | M11: =K11*L11 -> 0 | N11: =M11*0.75 -> 0
N12: =SUM(N8:N11) -> 2601.775
C13: BAJAS POR MATERNIDAD
A15: N° | B15: NOMBRE | C15: BAJA MEDICA | E15: DIA | F15: LA PAZ | H15: DIA | J15: TOTAL GANADO | K15: TOTAL DIA | L15: DIAS CBES | M15: TOTAL | N15: TOTAL (90%) | O15: OBSERVACION
C16: Empiezo | D16: Termino | F16: DE | G16: A
C17: 0 | D17: 0 | E17: =D17-C17+1 -> 1 | H17: =G17-F17+1 -> 1 | J17: 0 | K17: =J17/30 -> 0 | M17: =K17*L17 -> 0 | N17: =M17*0.9 -> 0
E18: =D18-C18+1 -> 1 | H18: =G18-F18+1 -> 1 | J18: 0 | K18: =J18/30 -> 0 | M18: =K18*L18 -> 0 | N18: =M18*0.9 -> 0
E19: =D19-C19+1 -> 1 | H19: =G19-F19+1 -> 1 | J19: 0 | K19: =J19/30 -> 0 | M19: =K19*L19 -> 0 | N19: =M19*0.9 -> 0
N20: =SUM(N17:N19) -> 0
C21: ACCIDENTE DE TRABAJO
A23: N° | B23: NOMBRE | C23: BAJA MEDICA | E23: DIA | F23: LA PAZ | H23: DIA | J23: TOTAL GANADO | K23: TOTAL DIA | L23: DIAS CBES | M23: TOTAL | N23: TOTAL (90%) | O23: OBSERVACION
C24: Empiezo | D24: Termino | F24: DE | G24: A
C25: 0 | D25: 0 | E25: =D25-C25+1 -> 1 | H25: =G25-F25+1 -> 1 | J25: 0 | K25: =J25/30 -> 0 | M25: =K25*L25 -> 0 | N25: =M25*0.9 -> 0
E26: =D26-C26+1 -> 1 | H26: =G26-F26+1 -> 1 | J26: 0 | K26: =J26/30 -> 0 | M26: =K26*L26 -> 0 | N26: =M26*0.9 -> 0
E27: =D27-C27+1 -> 1 | H27: =G27-F27+1 -> 1 | J27: 0 | K27: =J27/30 -> 0 | M27: =K27*L27 -> 0 | N27: =M27*0.9 -> 0
N28: =SUM(N25:N27) -> 0
K30: TOTAL REEMB | N30: =N28+N20+N12 -> 2601.775

Sheet MUSEF
A1: CAJA BANCARIA ESTATAL DE SALUD | N1: Nº. PATRONAL: 11-929-0001
A2: COTIZACIONES
A3: FUNDACION CULTURAL - MUSEF
F4: ENFERMEDAD COMUN
A5: N° | B5: NOMBRE | C5: BAJA MEDICA | E5: DIA | F5: LA PAZ | H5: DIA | J5: TOTAL GANADO | K5: TOTAL DIA | L5: DIAS CBES | M5: TOTAL | N5: TOTAL (75%) | O5: OBSERVACION
C6: Empiezo | D6: Termino | F6: DE | G6: A
C7: 0 | D7: 0 | E7: =D7-C7+1 -> 1 | F7: 0 | G7: 0 | H7: =G7-F7+1 -> 1 | I7: =H7-3 -> -2 | K7: =J7/30 -> 0 | M7: =K7*L7 -> 0 | N7: =M7*0.75 -> 0
A8: 1 | B8: ARANO ROMERO LUIS SALVADOR | C8: 45348 | D8: 45356 | E8: =D8-C8+1 -> 9 | F8: 45352 | G8: 45356 | H8: =G8-F8+1 -> 5 | I8: =H8-3 -> 2 | J8: 13553 | K8: =J8/30 -> 451.76667 | M8: =K8*L8 -> 0 | N8: =M8*0.75 -> 0
E9: =D9-C9+1 -> 1 | H9: =G9-F9+1 -> 1 | I9: =H9-3 -> -2 | K9: =J9/30 -> 0 | M9: =K9*L9 -> 0 | N9: =M9*0.75 -> 0
N10: =SUM(N7:N9) -> 0
F11: BAJAS POR MATERNIDAD
A13: N° | B13: NOMBRE | C13: BAJA MEDICA | E13: DIA | F13: LA PAZ | H13: DIA | J13: TOTAL GANADO | K13: TOTAL DIA | L13: DIAS CBES | M13: TOTAL | N13: TOTAL (90%) | O13: OBSERVACION
C14: Empiezo | D14: Termino | F14: DE | G14: A
E15: =D15-C15+1 -> 1 | G15: 0 | H15: =G15-F15+1 -> 1 | J15: 0 | K15: =J15/30 -> 0 | L15: 0 | M15: =K15*L15 -> 0 | N15: =M15*0.9 -> 0
A16: 1 | E16: =D16-C16+1 -> 1 | H16: =G16-F16+1 -> 1 | K16: =J16/30 -> 0 | M16: =K16*L16 -> 0 | N16: =M16*0.9 -> 0
E17: =D17-C17+1 -> 1 | G17: 0 | H17: =G17-F17+1 -> 1 | J17: 0 | K17: =J17/30 -> 0 | L17: 0 | M17: =K17*L17 -> 0 | N17: =M17*0.9 -> 0
N18: =SUM(N15:N17) -> 0
F19: ACCIDENTE DE TRABAJO
A21: N° | B21: NOMBRE | C21: BAJA MEDICA | E21: DIA | F21: LA PAZ | H21: DIA | J21: TOTAL GANADO | K21: TOTAL DIA | L21: DIAS CBES | M21: TOTAL | N21: TOTAL (90%) | O21: OBSERVACION
C22: Empiezo | D22: Termino | F22: DE | G22: A
C23: 0 | D23: 0 | E23: =D23-C23+1 -> 1 | F23: 36892 | G23: 36892 | H23: =G23-F23+1 -> 1 | J23: 0 | K23: =J23/30 -> 0 | L23: 0 | M23: =K23*L23 -> 0 | N23: =M23*0.9 -> 0
E24: =D24-C24+1 -> 1 | H24: =G24-F24+1 -> 1 | J24: 0 | K24: =J24/30 -> 0 | L24: 0 | M24: =K24*L24 -> 0 | N24: =M24*0.9 -> 0
E25: =D25-C25+1 -> 1 | H25: =G25-F25+1 -> 1 | J25: 0 | K25: =J25/30 -> 0 | L25: 0 | M25: =K25*L25 -> 0 | N25: =M25*0.9 -> 0
N26: =SUM(N23:N25) -> 0
K28: TOTAL REEMB | N28: =N26+N18+N10 -> 0

Sheet MEFP
A1: CAJA BANCARIA ESTATAL DE SALUD | N1: Nº PATRONAL : | O1: 11-911-0001
A2: COTIZACIONES
A3: MINISTERIO DE ECONOMIA Y FINANZAS PUBLICAS
C4: ENFERMEDAD COMUN
A5: N° | B5: NOMBRE | C5: BAJA MEDICA | F5: Correspondiente al mes | H5: DIA | J5: TOTAL GANADO | K5: TOTAL DIA | L5: DIAS CBES | M5: TOTAL | N5: TOTAL (75%) | O5: OBSERVACION
C6: Empiezo | D6: Termino | F6: DE | G6: A
C7: 0 | D7: 0 | F7: 0 | G7: 0 | H7: =G7-F7+1 -> 1 | I7: =H7-3 -> -2 | J7: 0 | K7: =J7/30 -> 0 | M7: =K7*L7 -> 0 | N7: =M7*0.75 -> 0
A8: 1 | B8: DELGADO VILLARREAL JAVIER | C8: 45680 | D8: 45688 | E8: =D8-C8+1 -> 9 | F8: 45680 | G8: 45687 | H8: =G8-F8+1 -> 8 | I8: =H8-3 -> 5 | J8: 14327 | K8: =J8/30 -> 477.56667 | L8: =+I8 -> 5 | M8: =K8*L8 -> 2387.8333 | N8: =M8*0.75 -> 1790.875
A9: 2 | B9: RIOS RIOS FERNANDO OMAR | C9: 45565 | D9: 45691 | E9: =D9-C9+1 -> 127 | F9: 45658 | G9: 45687 | H9: =G9-F9+1 -> 30 | I9: =H9-3 -> 27 | J9: 10268 | K9: =J9/30 -> 342.26667 | L9: 30 | M9: =K9*L9 -> 10268 | N9: =M9*0.75 -> 7701
A10: 3 | B10: URQUIDI VELASQUEZ MARIA LAURA | C10: 45667 | D10: 45681 | E10: =D10-C10+1 -> 15 | F10: 45668 | G10: 45681 | H10: =G10-F10+1 -> 14 | I10: =H10-3 -> 11 | J10: 12329 | K10: =J10/30 -> 410.96667 | L10: =+I10 -> 11 | M10: =K10*L10 -> 4520.6333 | N10: =M10*0.75 -> 3390.475 | O10: FH
A11: 4 | B11: URQUIDI VELASQUEZ MARIA LAURA | C11: 45685 | D11: 45688 | E11: =D11-C11+1 -> 4 | F11: 45685 | G11: 45687 | H11: =G11-F11+1 -> 3 | I11: =H11-3 -> 0 | J11: 12329 | K11: =J11/30 -> 410.96667 | L11: =+I11 -> 0 | M11: =K11*L11 -> 0 | N11: =M11*0.75 -> 0
A12: 5 | B12: ZURITA FLORES HENRY | C12: 45665 | D12: 45692 | E12: =D12-C12+1 -> 28 | F12: 45665 | G12: 45687 | H12: =G12-F12+1 -> 23 | I12: =H12-3 -> 20 | J12: 14061 | K12: =J12/30 -> 468.7 | L12: =+I12 -> 20 | M12: =K12*L12 -> 9374 | N12: =M12*0.75 -> 7030.5
A13: 6 | B13: QUISPE PERCA GLADYS | C13: 45657 | D13: 45691 | E13: =D13-C13+1 -> 35 | F13: 45658 | G13: 45687 | H13: =G13-F13+1 -> 30 | I13: =H13-3 -> 27 | J13: 7078 | K13: =J13/30 -> 235.93333 | L13: =+I13 -> 27 | M13: =K13*L13 -> 6370.2 | N13: =+M13*0.75 -> 4777.65
N14: =SUM(N8:N13) -> 24690.5
F15: BAJAS POR MATERNIDAD
A17: N° | B17: NOMBRE | C17: BAJA MEDICA | E17: DIA | F17: Correspondiente al mes | H17: DIA | J17: TOTAL GANADO | K17: TOTAL DIA | L17: DIAS CBES | M17: TOTAL | N17: TOTAL (90%) | O17: OBSERVACION
C18: Empiezo | D18: Termino | F18: DE | G18: A
E19: =D19-C19+1 -> 1 | F19: 0 | G19: 0 | H19: =G19-F19+1 -> 1 | J19: 0 | K19: =J19/30 -> 0 | M19: =K19*L19 -> 0 | N19: =M19*0.9 -> 0
A20: 1 | B20: MAMANI LIMACHI EDITH | C20: 45672 | D20: 45716 | E20: =D20-C20+1 -> 45 | F20: 45672 | G20: 45687 | H20: =G20-F20+1 -> 16 | J20: 10296 | K20: =J20/30 -> 343.2 | L20: =+H20 -> 16 | M20: =+L20*K20 -> 5491.2 | N20: =M20*0.9 -> 4942.08
E21: =D21-C21+1 -> 1 | H21: =G21-F21+1 -> 1 | K21: =J21/30 -> 0 | M21: =+L21*K21 -> 0 | N21: =M21*0.9 -> 0
N22: =SUM(N19:N21) -> 4942.08
F23: ACCIDENTE DE TRABAJO
A25: N° | B25: NOMBRE | C25: BAJA MEDICA | F25: Correspondiente al mes | H25: DIA | J25: TOTAL GANADO | K25: TOTAL DIA | L25: DIAS CBES | M25: TOTAL | N25: TOTAL (90%) | O25: OBSERVACION
C26: Empiezo | D26: Termino | F26: DE | G26: A
F27: 0 | G27: 0 | H27: =G27-F27+1 -> 1 | J27: 0 | K27: =J27/30 -> 0 | M27: =K27*L27 -> 0 | N27: =M27*0.9 -> 0
A28: 1 | B28: SANTOS ALVAREZ WINDY JAQUELINE | C28: 45638 | D28: 45674 | F28: 45658 | G28: 45674 | H28: =G28-F28+1 -> 17 | J28: 8842 | K28: =J28/30 -> 294.73333 | L28: =+H28 -> 17 | M28: =K28*L28 -> 5010.4667 | N28: =M28*0.9 -> 4509.42
H29: =G29-F29+1 -> 1 | K29: =J29/30 -> 0 | M29: =K29*L29 -> 0 | N29: =M29*0.9 -> 0
N30: =SUM(N27:N29) -> 4509.42
K32: TOTAL REEMB | N32: =N14+N22+N30 -> 34142

Sheet ENS
A1: CAJA BANCARIA ESTATAL DE SALUD | M1: Nº PATRONAL: | O1: 11-911-0007
A2: COTIZACIONES
A3: ESCUELA NACIONAL DE SALUD
C4: ENFERMEDAD COMUN
A5: N° | B5: NOMBRE | C5: BAJA MEDICA | F5: Correspondiente al mes | H5: DIA | J5: TOTAL GANADO | K5: TOTAL DIA | L5: DIAS CBES | M5: TOTAL | N5: TOTAL (75%) | O5: OBSERVACION
C6: Empiezo | D6: Termino | F6: DE | G6: A
F7: 0 | G7: 0 | H7: =G7-F7+1 -> 1 | I7: =H7-3 -> -2 | J7: 0 | K7: =J7/30 -> 0 | M7: =K7*L7 -> 0 | N7: =M7*0.75 -> 0
A8: 1 | E8: =D8-C8+1 -> 1 | H8: =G8-F8+1 -> 1 | I8: =H8-3 -> -2 | K8: =J8/30 -> 0 | M8: =K8*L8 -> 0 | N8: =M8*0.75 -> 0
E9: =D9-C9+1 -> 1 | H9: =G9-F9+1 -> 1 | I9: =H9-3 -> -2 | K9: =J9/30 -> 0 | M9: =K9*L9 -> 0 | N9: =M9*0.75 -> 0
E10: =D10-C10+1 -> 1 | H10: =G10-F10+1 -> 1 | I10: =H10-3 -> -2 | K10: =J10/30 -> 0 | M10: =K10*L10 -> 0 | N10: =M10*0.75 -> 0
N11: =SUM(N7:N10) -> 0
C12: BAJAS POR MATERNIDAD
A14: N° | B14: NOMBRE | C14: BAJA MEDICA | F14: Correspondiente al mes | H14: DIA | J14: TOTAL GANADO | K14: TOTAL DIA | L14: DIAS CBES | M14: TOTAL | N14: TOTAL (90%) | O14: OBSERVACION
C15: Empiezo | D15: Termino | F15: DE | G15: A
C16: 0 | D16: 0 | E16: =D16-C16+1 -> 1 | F16: 0 | G16: 0 | H16: =G16-F16+1 -> 1 | J16: 0 | K16: =J16/30 -> 0 | L16: 0 | M16: =K16*L16 -> 0 | N16: =M16*0.9 -> 0
E17: =D17-C17+1 -> 1 | H17: =G17-F17+1 -> 1 | K17: =J17/30 -> 0 | M17: =K17*L17 -> 0 | N17: =M17*0.9 -> 0
E18: =D18-C18+1 -> 1 | H18: =G18-F18+1 -> 1 | K18: =J18/30 -> 0 | M18: =K18*L18 -> 0 | N18: =M18*0.9 -> 0
N19: =SUM(N16:N18) -> 0
C20: ACCIDENTE DE TRABAJO
A22: N° | B22: NOMBRE | C22: BAJA MEDICA | F22: Correspondiente al mes | J22: TOTAL GANADO | K22: TOTAL DIA | L22: DIAS CBES | M22: TOTAL | N22: TOTAL (90%) | O22: OBSERVACION
C23: Empiezo | D23: Termino | F23: DE | G23: A
C24: 0 | D24: 0 | F24: 0 | G24: 0 | H24: =G24-F24+1 -> 1 | J24: 0 | K24: =J24/30 -> 0 | M24: =K24*L24 -> 0 | N24: =M24*0.9 -> 0
H25: =G25-F25+1 -> 1 | J25: 0 | K25: =J25/30 -> 0 | M25: =K25*L25 -> 0 | N25: =M25*0.9 -> 0
H26: =G26-F26+1 -> 1 | J26: 0 | K26: =J26/30 -> 0 | M26: =K26*L26 -> 0 | N26: =M26*0.9 -> 0
N27: =SUM(N24:N26) -> 0
K29: TOTAL REEMB | N29: =N27+N19+N11 -> 0

Sheet ETS
A1: CAJA BANCARIA ESTATAL DE SALUD | M1: Nº PATRONAL: | O1: 21-911-0006
A2: COTIZACIONES
A3: ESCUELA TECNICA DE SALUD
C4: ENFERMEDAD COMUN
A5: N° | B5: NOMBRE | C5: BAJA MEDICA | F5: Correspondiente al mes | H5: DIA | J5: TOTAL GANADO | K5: TOTAL DIA | L5: DIAS CBES | M5: TOTAL | N5: TOTAL (75%) | O5: OBSERVACION
C6: Empiezo | D6: Termino | F6: DE | G6: A
F7: 0 | G7: 0 | H7: =G7-F7+1 -> 1 | I7: =H7-3 -> -2 | J7: 0 | K7: =J7/30 -> 0 | M7: =K7*L7 -> 0 | N7: =M7*0.75 -> 0
A8: 1 | E8: =D8-C8+1 -> 1 | H8: =G8-F8+1 -> 1 | I8: =H8-3 -> -2 | K8: =J8/30 -> 0 | M8: =K8*L8 -> 0 | N8: =M8*0.75 -> 0
A9: 2 | E9: =D9-C9+1 -> 1 | H9: =G9-F9+1 -> 1 | I9: =H9-3 -> -2 | K9: =J9/30 -> 0 | M9: =K9*L9 -> 0 | N9: =M9*0.75 -> 0
E10: =D10-C10+1 -> 1 | H10: =G10-F10+1 -> 1 | I10: =H10-3 -> -2 | K10: =J10/30 -> 0 | M10: =K10*L10 -> 0 | N10: =M10*0.75 -> 0
N11: =SUM(N7:N10) -> 0
C12: BAJAS POR MATERNIDAD
A14: N° | B14: NOMBRE | C14: BAJA MEDICA | F14: Correspondiente al mes | H14: DIA | J14: TOTAL GANADO | K14: TOTAL DIA | L14: DIAS CBES | M14: TOTAL | N14: TOTAL (90%) | O14: OBSERVACION
C15: Empiezo | D15: Termino | F15: DE | G15: A
C16: 0 | D16: 0 | E16: =D16-C16+1 -> 1 | F16: 0 | G16: 0 | H16: =G16-F16+1 -> 1 | J16: 0 | K16: =J16/30 -> 0 | M16: =K16*L16 -> 0 | N16: =M16*0.9 -> 0
A17: 1 | B17: PAINA CORDOVA ESTHER | C17: 45544 | D17: 45633 | E17: =D17-C17+1 -> 90 | F17: 45627 | G17: 45633 | H17: =G17-F17+1 -> 7 | I17: 30 | J17: 5284 | K17: =J17/30 -> 176.13333 | L17: =+H17 -> 7 | M17: =K17*L17 -> 1232.9333 | N17: =M17*0.9 -> 1109.64
E18: =D18-C18+1 -> 1 | H18: =G18-F18+1 -> 1 | I18: 30 | K18: =J18/30 -> 0 | M18: =K18*L18 -> 0 | N18: =M18*0.9 -> 0
N20: =SUM(N16:N19) -> 1109.64
C21: ACCIDENTE DE TRABAJO
A23: N° | B23: NOMBRE | C23: BAJA MEDICA | F23: Correspondiente al mes | J23: TOTAL GANADO | K23: TOTAL DIA | L23: DIAS CBES | M23: TOTAL | N23: TOTAL (90%) | O23: OBSERVACION
C24: Empiezo | D24: Termino | F24: DE | G24: A
C25: 0 | D25: 0 | F25: 0 | G25: 0 | H25: =G25-F25+1 -> 1 | J25: 0 | K25: =J25/30 -> 0 | M25: =K25*L25 -> 0 | N25: =M25*0.9 -> 0
A26: 1 | H26: =G26-F26+1 -> 1 | K26: =J26/30 -> 0 | M26: =K26*L26 -> 0 | N26: =M26*0.9 -> 0
H27: =G27-F27+1 -> 1 | K27: =J27/30 -> 0 | M27: =K27*L27 -> 0 | N27: =M27*0.9 -> 0
N28: =SUM(N25:N27) -> 0
K30: TOTAL REEMB | N30: =N28+N20+N11 -> 1109.64

Sheet EDITORIAL
A1: CAJA BANCARIA ESTATAL DE SALUD | M1: Nº PATRONAL: | O1: 11-911-0005
A2: COTIZACIONES
A3: EDITORIAL DEL ESTADO
C4: ENFERMEDAD COMUN
A5: N° | B5: NOMBRE | C5: BAJA MEDICA | F5: Correspondiente al mes | H5: DIA | J5: TOTAL GANADO | K5: TOTAL DIA | L5: DIAS CBES | M5: TOTAL | N5: TOTAL (75%) | O5: OBSERVACION
C6: Empiezo | D6: Termino | F6: DE | G6: A
F7: 0 | G7: 0 | H7: =G7-F7+1 -> 1 | I7: =H7-3 -> -2 | J7: 0 | K7: =J7/30 -> 0 | M7: =K7*L7 -> 0 | N7: =M7*0.75 -> 0
A8: 1 | B8: MAMANI MARCA RUTH JUDITH | E8: =D8-C8+1 -> 1 | F8: 45612 | G8: 45615 | H8: =G8-F8+1 -> 4 | I8: =H8-3 -> 1 | J8: 6100 | K8: =J8/30 -> 203.33333 | M8: =K8*L8 -> 0 | N8: =M8*0.75 -> 0
E9: =D9-C9+1 -> 1 | H9: =G9-F9+1 -> 1 | I9: =H9-3 -> -2 | M9: =K9*L9 -> 0 | N9: =M9*0.75 -> 0
N11: =SUM(N7:N10) -> 0
C12: BAJAS POR MATERNIDAD
A14: N° | B14: NOMBRE | C14: BAJA MEDICA | F14: Correspondiente al mes | H14: DIA | J14: TOTAL GANADO | K14: TOTAL DIA | L14: DIAS CBES | M14: TOTAL | N14: TOTAL (90%) | O14: OBSERVACION
C15: Empiezo | D15: Termino | F15: DE | G15: A
C16: 0 | D16: 0 | E16: =D16-C16+1 -> 1 | F16: 0 | G16: 0 | H16: =G16-F16+1 -> 1 | J16: 0 | K16: =J16/30 -> 0 | L16: 0 | M16: =K16*L16 -> 0 | N16: =M16*0.9 -> 0
A17: 1 | E17: =D17-C17+1 -> 1 | H17: =G17-F17+1 -> 1 | K17: =J17/30 -> 0 | M17: =K17*L17 -> 0 | N17: =M17*0.9 -> 0
E18: =D18-C18+1 -> 1 | H18: =G18-F18+1 -> 1 | K18: =J18/30 -> 0 | L18: 0 | M18: =K18*L18 -> 0 | N18: =M18*0.9 -> 0
N19: =SUM(N16:N18) -> 0
C20: ACCIDENTE DE TRABAJO
A22: N° | B22: NOMBRE | C22: BAJA MEDICA | F22: Correspondiente al mes | J22: TOTAL GANADO | K22: TOTAL DIA | L22: DIAS CBES | M22: TOTAL | N22: TOTAL (90%) | O22: OBSERVACION
C23: Empiezo | D23: Termino | F23: DE | G23: A
C24: 0 | D24: 0 | F24: 0 | G24: 0 | H24: =G24-F24+1 -> 1 | J24: 0 | K24: =J24/30 -> 0 | M24: =K24*L24 -> 0 | N24: =M24*0.9 -> 0
H25: =G25-F25+1 -> 1 | K25: =J25/30 -> 0 | M25: =K25*L25 -> 0 | N25: =M25*0.9 -> 0
H26: =G26-F26+1 -> 1 | K26: =J26/30 -> 0 | M26: =K26*L26 -> 0 | N26: =M26*0.9 -> 0
N27: =SUM(N24:N26) -> 0
K29: TOTAL REEMB | N29: =N27+N19+N11 -> 0

Sheet AFCOOP
A1: CAJA BANCARIA ESTATAL DE SALUD
A2: COTIZACIONES | N2: Nº. PATRONAL: | O2: 11-911-0002
A3: AFCOOP
C4: ENFERMEDAD COMUN
A5: N° | B5: NOMBRE | C5: BAJA MEDICA | F5: Correspondiente al mes | H5: DIA | J5: TOTAL GANADO | K5: TOTAL DIA | L5: DIAS CBES | M5: TOTAL | N5: TOTAL (75%) | O5: OBSERVACION
C6: Empiezo | D6: Termino | F6: DE | G6: A
F7: 0 | G7: 0 | H7: =G7-F7+1 -> 1 | I7: =H7-3 -> -2 | J7: 0 | K7: =J7/30 -> 0 | M7: =K7*L7 -> 0 | N7: =M7*0.75 -> 0
A8: 1 | B8: AVILES LUNA WENDY MARIBEL | E8: =D8-C8+1 -> 1 | F8: 45435 | G8: 45438 | H8: =G8-F8+1 -> 4 | I8: =H8-3 -> 1 | J8: 4788 | K8: =J8/30 -> 159.6 | M8: =K8*L8 -> 0 | N8: =M8*0.75 -> 0
A9: 2 | E9: =D9-C9+1 -> 1 | H9: =G9-F9+1 -> 1 | I9: =H9-3 -> -2 | K9: =J9/30 -> 0 | M9: =K9*L9 -> 0 | N9: =M9*0.75 -> 0
E10: =D10-C10+1 -> 1 | H10: =G10-F10+1 -> 1 | I10: =H10-3 -> -2 | K10: =J10/30 -> 0 | M10: =K10*L10 -> 0 | N10: =M10*0.75 -> 0
N11: =SUM(N7:N10) -> 0
C12: BAJAS POR MATERNIDAD
A14: N° | B14: NOMBRE | C14: BAJA MEDICA | F14: Correspondiente al mes | H14: DIA | J14: TOTAL GANADO | K14: TOTAL DIA | L14: DIAS CBES | M14: TOTAL | N14: TOTAL (90%) | O14: OBSERVACION
C15: Empiezo | D15: Termino | F15: DE | G15: A
C16: 0 | D16: 0 | E16: =D16-C16+1 -> 1 | F16: 0 | G16: 0 | H16: =G16-F16+1 -> 1 | J16: 0 | K16: =J16/30 -> 0 | L16: 0 | M16: =K16*L16 -> 0 | N16: =M16*0.9 -> 0
A17: 1 | E17: =D17-C17+1 -> 1 | H17: =G17-F17+1 -> 1 | K17: =+J17/30 -> 0 | M17: =K17*L17 -> 0 | N17: =M17*0.9 -> 0
E18: =D18-C18+1 -> 1 | H18: =G18-F18+1 -> 1 | K18: =J18/30 -> 0 | M18: =K18*L18 -> 0 | N18: =M18*0.9 -> 0
N19: =SUM(N16:N18) -> 0
C20: ACCIDENTE DE TRABAJO
A22: N° | B22: NOMBRE | C22: BAJA MEDICA | F22: Correspondiente al mes | J22: TOTAL GANADO | K22: TOTAL DIA | L22: DIAS CBES | M22: TOTAL | N22: TOTAL (90%) | O22: OBSERVACION
C23: Empiezo | D23: Termino | F23: DE | G23: A
C24: 0 | D24: 0 | F24: 0 | G24: 0 | H24: =G24-F24+1 -> 1 | J24: 0 | K24: =J24/30 -> 0 | M24: =K24*L24 -> 0 | N24: =M24*0.9 -> 0
H25: =G25-F25+1 -> 1 | J25: 0 | K25: =J25/30 -> 0 | M25: =K25*L25 -> 0 | N25: =M25*0.9 -> 0
H26: =G26-F26+1 -> 1 | J26: 0 | K26: =J26/30 -> 0 | M26: =K26*L26 -> 0 | N26: =M26*0.9 -> 0
N27: =SUM(N24:N26) -> 0
K29: TOTAL REEMB | N29: =N27+N19+N11 -> 0

Sheet AISEM
A1: CAJA BANCARIA ESTATAL DE SALUD | M1: Nº PATRONAL : | O1: 11-911-0004
A2: COTIZACIONES
A3: AISEM
C4: ENFERMEDAD COMUN
A5: N° | B5: NOMBRE | C5: BAJA MEDICA | F5: Correspondiente al mes | H5: DIA | J5: TOTAL GANADO | K5: TOTAL DIA | L5: DIAS CBES | M5: TOTAL | N5: TOTAL (75%) | O5: OBSERVACION
C6: Empiezo | D6: Termino | F6: DE | G6: A
F7: 0 | G7: 0 | H7: =G7-F7+1 -> 1 | I7: =H7-3 -> -2 | J7: 0 | K7: =J7/30 -> 0 | M7: =K7*L7 -> 0 | N7: =M7*0.75 -> 0
A8: 1 | B8: FLORES FLORES IRWIN | C8: 45650 | D8: 45674 | E8: =D8-C8+1 -> 25 | F8: 45658 | G8: 45674 | H8: =G8-F8+1 -> 17 | I8: =H8-3 -> 14 | J8: 5139 | K8: =J8/30 -> 171.3 | L8: 17 | M8: =K8*L8 -> 2912.1 | N8: =M8*0.75 -> 2184.075
A9: 2 | B9: CHAVARRIA NUÑEZ MARIA LUISA | C9: 45648 | D9: 45666 | E9: =D9-C9+1 -> 19 | F9: 45658 | G9: 45666 | H9: =G9-F9+1 -> 9 | I9: =H9-3 -> 6 | J9: 18366 | K9: =J9/30 -> 612.2 | L9: 9 | M9: =K9*L9 -> 5509.8 | N9: =M9*0.75 -> 4132.35
N10: =SUM(N7:N9) -> 6316.425
C11: BAJAS POR MATERNIDAD
A13: N° | B13: NOMBRE | C13: BAJA MEDICA | F13: Correspondiente al mes | H13: DIA | J13: TOTAL GANADO | K13: TOTAL DIA | L13: DIAS CBES | M13: TOTAL | N13: TOTAL (90%) | O13: OBSERVACION
C14: Empiezo | D14: Termino | F14: DE | G14: A
C15: 0 | D15: 0 | E15: =D15-C15+1 -> 1 | F15: 0 | G15: 0 | H15: =G15-F15+1 -> 1 | J15: 0 | K15: =J15/30 -> 0 | L15: 0 | M15: =K15*L15 -> 0 | N15: =M15*0.9 -> 0
A16: 1 | E16: =D16-C16+1 -> 1 | H16: =G16-F16+1 -> 1 | K16: =J16/30 -> 0 | M16: =K16*L16 -> 0 | N16: =M16*0.9 -> 0
A17: 1
N18: =SUM(N15:N17) -> 0
C19: ACCIDENTE DE TRABAJO
A21: N° | B21: NOMBRE | C21: BAJA MEDICA | F21: Correspondiente al mes | J21: TOTAL GANADO | K21: TOTAL DIA | L21: DIAS CBES | M21: TOTAL | N21: TOTAL (90%) | O21: OBSERVACION
C22: Empiezo | D22: Termino | F22: DE | G22: A
C23: 0 | D23: 0 | F23: 0 | G23: 0 | H23: =G23-F23+1 -> 1 | J23: 0 | K23: =J23/30 -> 0 | M23: =K23*L23 -> 0 | N23: =M23*0.9 -> 0
A24: 1 | H24: =G24-F24+1 -> 1 | K24: =J24/30 -> 0 | M24: =K24*L24 -> 0 | N24: =M24*0.9 -> 0
H25: =G25-F25+1 -> 1 | J25: 0 | K25: =J25/30 -> 0 | M25: =K25*L25 -> 0 | N25: =M25*0.9 -> 0
N26: =SUM(N23:N25) -> 0
K28: TOTAL REEMB | N28: =N26+N18+N10 -> 6316.425

Sheet CENETROP
A1: CAJA BANCARIA ESTATAL DE SALUD | M1: Nº PATRONAL: | O1: 61-923-0001
A2: COTIZACIONES
D3: CENETROP
C5: ENFERMEDAD COMUN
A6: N° | B6: NOMBRE | F6: Correspondiente al mes | H6: DIA | J6: TOTAL GANADO | K6: TOTAL DIA | L6: DIAS CBES | M6: TOTAL | N6: TOTAL (75%) | O6: OBSERVACION
C7: Empiezo | D7: Termino | F7: DE | G7: A
F8: 0 | G8: 0 | H8: =G8-F8+1 -> 1 | I8: =H8-3 -> -2 | J8: 0 | K8: =J8/30 -> 0 | M8: =K8*L8 -> 0 | N8: =M8*0.75 -> 0
A9: 1 | H9: =G9-F9+1 -> 1 | I9: =H9-3 -> -2 | K9: =J9/30 -> 0 | M9: =K9*L9 -> 0 | N9: =M9*0.75 -> 0
A10: 2 | H10: =G10-F10+1 -> 1 | I10: =H10-3 -> -2 | K10: =J10/30 -> 0 | M10: =K10*L10 -> 0 | N10: =M10*0.75 -> 0
N11: =SUM(N8:N10) -> 0
C12: BAJAS POR MATERNIDAD
A14: N° | B14: NOMBRE | C14: BAJA MEDICA | F14: Correspondiente al mes | H14: DIA | J14: TOTAL GANADO | K14: TOTAL DIA | L14: DIAS CBES | M14: TOTAL | N14: TOTAL (90%) | O14: OBSERVACION
C15: Empiezo | D15: Termino | F15: DE | G15: A
C16: 0 | D16: 0 | E16: =D16-C16+1 -> 1 | F16: 0 | G16: 0 | H16: =G16-F16+1 -> 1 | J16: 0 | K16: =J16/30 -> 0 | L16: 0 | M16: =K16*L16 -> 0 | N16: =M16*0.9 -> 0
E17: =D17-C17+1 -> 1 | H17: =G17-F17+1 -> 1 | J17: 0 | K17: =J17/30 -> 0 | L17: 0 | M17: =K17*L17 -> 0 | N17: =M17*0.9 -> 0
E18: =D18-C18+1 -> 1 | H18: =G18-F18+1 -> 1 | J18: 0 | K18: =J18/30 -> 0 | L18: 0 | M18: =K18*L18 -> 0 | N18: =M18*0.9 -> 0
N19: =SUM(N16:N18) -> 0
C20: ACCIDENTE DE TRABAJO
A22: N° | B22: NOMBRE | C22: BAJA MEDICA | F22: Correspondiente al mes | J22: TOTAL GANADO | K22: TOTAL DIA | L22: DIAS CBES | M22: TOTAL | N22: TOTAL (90%) | O22: OBSERVACION
C23: Empiezo | D23: Termino | F23: DE | G23: A
C24: 0 | D24: 0 | F24: 0 | G24: 0 | H24: =G24-F24+1 -> 1 | J24: 0 | K24: =J24/30 -> 0 | M24: =K24*L24 -> 0 | N24: =M24*0.9 -> 0
H25: =G25-F25+1 -> 1 | J25: 0 | K25: =J25/30 -> 0 | M25: =K25*L25 -> 0 | N25: =M25*0.9 -> 0
H26: =G26-F26+1 -> 1 | J26: 0 | K26: =J26/30 -> 0 | M26: =K26*L26 -> 0 | N26: =M26*0.9 -> 0
N27: =SUM(N24:N26) -> 0
K29: TOTAL REEMB | N29: =N27+N19+N11 -> 0

Sheet CEASS
A1: CAJA BANCARIA ESTATAL DE SALUD | M1: Nº1 PATRONAL: | O1: 11-911-0008
A2: COTIZACIONES
A3: CEASS
C4: ENFERMEDAD COMUN
A5: N° | B5: NOMBRE | C5: BAJA MEDICA | F5: LA PAZ | H5: DIA | I5: CBES | J5: TOTAL GANADO | K5: TOTAL DIA | L5: DIAS CBES | M5: TOTAL | N5: TOTAL (75%) | O5: OBSERVACION
C6: Empiezo | D6: Termino | F6: DE | G6: A
C7: 0 | D7: 0 | F7: 0 | G7: 0 | H7: =G7-F7+1 -> 1 | I7: =H7-3 -> -2 | J7: 0 | K7: =J7/30 -> 0 | M7: =K7*L7 -> 0 | N7: =M7*0.75 -> 0
A8: 1 | B8: BALLESTEROS COCA JOSE ROBERTO | F8: 45665 | G8: 45678 | H8: =G8-F8+1 -> 14 | I8: =H8-3 -> 11 | J8: 17693 | K8: =J8/30 -> 589.76667 | L8: =+I8 -> 11 | M8: =K8*L8 -> 6487.4333 | N8: =M8*0.75 -> 4865.575
A9: 2 | B9: SANTA CRUZ RIOS LEON JORGE | F9: 45659 | G9: 45664 | H9: =G9-F9+1 -> 6 | I9: =H9-3 -> 3 | J9: 7245 | K9: =J9/30 -> 241.5 | L9: =+I9 -> 3 | M9: =K9*L9 -> 724.5 | N9: =M9*0.75 -> 543.375
N11: =SUM(N7:N10) -> 5408.95
C12: BAJAS POR MATERNIDAD
A14: N° | B14: NOMBRE | C14: BAJA MEDICA | E14: DIA | F14: LA PAZ | H14: DIA | J14: TOTAL GANADO | K14: TOTAL DIA | L14: DIAS CBES | M14: TOTAL | N14: TOTAL (90%) | O14: OBSERVACION
C15: Empiezo | D15: Termino | F15: DE | G15: A
C16: 0 | D16: 0 | E16: =D16-C16+1 -> 1 | F16: 0 | G16: 0 | H16: =G16-F16+1 -> 1 | J16: 0 | K16: =J16/30 -> 0 | L16: 0 | M16: =K16*L16 -> 0 | N16: =M16*0.9 -> 0
A17: 1 | B17: GUARACHI CONDORI SELENA YAQUELINE | C17: 45590 | D17: 45679 | E17: =D17-C17+1 -> 90 | F17: 45658 | G17: 45679 | H17: =G17-F17+1 -> 22 | I17: =+H17 -> 22 | J17: 9310 | K17: =J17/30 -> 310.33333 | L17: =+I17 -> 22 | M17: =K17*L17 -> 6827.3333 | N17: =M17*0.9 -> 6144.6
E18: =D18-C18+1 -> 1 | H18: =G18-F18+1 -> 1 | J18: 0 | K18: =J18/30 -> 0 | L18: 0 | M18: =K18*L18 -> 0 | N18: =M18*0.9 -> 0
N19: =SUM(N16:N18) -> 6144.6
C20: ACCIDENTE DE TRABAJO
A22: N° | B22: NOMBRE | C22: BAJA MEDICA | F22: LA PAZ | H22: DIA | J22: TOTAL GANADO | K22: TOTAL DIA | L22: DIAS CBES | M22: TOTAL | N22: TOTAL (90%) | O22: OBSERVACION
C23: Empiezo | D23: Termino | F23: DE | G23: A
H24: =G24-F24+1 -> 1 | J24: 0 | K24: =J24/30 -> 0 | M24: =K24*L24 -> 0 | N24: =M24*0.9 -> 0
A25: 1 | B25: VILLCA GOMEZ EUGENIO | C25: 45652 | D25: 45692 | F25: 45658 | G25: 45687 | H25: =G25-F25+1 -> 30 | J25: 3804 | K25: =J25/30 -> 126.8 | L25: =+H25 -> 30 | M25: =K25*L25 -> 3804 | N25: =M25*0.9 -> 3423.6
N26: =SUM(N24:N25) -> 3423.6
K28: TOTAL REEMB | N28: =N11+N19+N26 -> 14977.15

Sheet PLANIFICACION
A1: MINISTERIO DE PLANIFICACION
C2: ENFERMEDAD COMUN
A3: N° | B3: NOMBRE | C3: BAJA MEDICA | F3: LA PAZ | H3: DIA | I3: CBES | J3: TOTAL GANADO | K3: TOTAL DIA | L3: DIAS CBES | M3: TOTAL | N3: TOTAL (75%) | O3: OBSERVACION
C4: Empiezo | D4: Termino | F4: DE | G4: A
C5: 0 | D5: 0 | F5: 0 | G5: 0 | H5: =G5-F5+1 -> 1 | I5: =H5-3 -> -2 | J5: 0 | K5: =J5/30 -> 0 | M5: =K5*L5 -> 0 | N5: =M5*0.75 -> 0
A6: 1 | E6: =+D6-C6+1 -> 1 | H6: =G6-F6+1 -> 1 | I6: =H6-3 -> -2 | K6: =J6/30 -> 0 | M6: =K6*L6 -> 0 | N6: =M6*0.75 -> 0
A7: 1 | E7: =+D7-C7+1 -> 1 | H7: =G7-F7+1 -> 1 | I7: =H7-3 -> -2 | K7: =J7/30 -> 0 | M7: =K7*L7 -> 0 | N7: =M7*0.75 -> 0
C8: 0 | D8: 0 | H8: =G8-F8+1 -> 1 | I8: =H8-3 -> -2 | K8: =J8/30 -> 0 | M8: =K8*L8 -> 0 | N8: =M8*0.75 -> 0
N9: =SUM(N5:N8) -> 0
C10: BAJAS POR MATERNIDAD
A12: N° | B12: NOMBRE | C12: BAJA MEDICA | E12: DIA | F12: LA PAZ | H12: DIA | J12: TOTAL GANADO | K12: TOTAL DIA | L12: DIAS CBES | M12: TOTAL | N12: TOTAL (90%) | O12: OBSERVACION
C13: Empiezo | D13: Termino | F13: DE | G13: A
C14: 0 | D14: 0 | E14: =D14-C14+1 -> 1 | F14: 0 | G14: 0 | H14: =G14-F14+1 -> 1 | J14: 0 | K14: =J14/30 -> 0 | L14: 0 | M14: =K14*L14 -> 0 | N14: =M14*0.9 -> 0
A15: 1 | E15: =D15-C15+1 -> 1 | H15: =G15-F15+1 -> 1 | K15: =J15/30 -> 0 | M15: =K15*L15 -> 0 | N15: =M15*0.9 -> 0
E16: =D16-C16+1 -> 1 | H16: =G16-F16+1 -> 1 | K16: =J16/30 -> 0 | L16: 0 | M16: =K16*L16 -> 0 | N16: =M16*0.9 -> 0
N17: =SUM(N14:N16) -> 0
C18: ACCIDENTE DE TRABAJO
A20: N° | B20: NOMBRE | C20: BAJA MEDICA | F20: LA PAZ | H20: DIA | J20: TOTAL GANADO | K20: TOTAL DIA | L20: DIAS CBES | M20: TOTAL | N20: TOTAL (90%) | O20: OBSERVACION
C21: Empiezo | D21: Termino | F21: DE | G21: A
F22: 44927 | G22: 44927 | H22: =G22-F22+1 -> 1 | J22: 0 | K22: =J22/30 -> 0 | M22: =K22*L22 -> 0 | N22: =M22*0.9 -> 0
A23: 1 | B23: ACHU TICONA BETTY SUSANA | F23: 45685 | G23: 45685 | H23: =G23-F23+1 -> 1 | J23: 21574 | K23: =J23/30 -> 719.13333 | L23: =+H23 -> 1 | M23: =K23*L23 -> 719.13333 | N23: =M23*0.9 -> 647.22
H24: =G24-F24+1 -> 1 | J24: 0 | K24: =J24/30 -> 0 | M24: =K24*L24 -> 0 | N24: =M24*0.9 -> 0
N25: =SUM(N22:N24) -> 647.22
K27: TOTAL REEMB | N27: =N9+N17+N25 -> 647.22

Sheet CANCILLERIA
A1: CAJA BANCARIA ESTATAL DE SALUD | M1: Nº1 PATRONAL: | O1: 11-911-0009
B2: COTIZACIONES
A3: MINISTERIO DE RELACIONES EXTERIORES
C4: ENFERMEDAD COMUN
A5: N° | B5: NOMBRE | C5: BAJA MEDICA | F5: LA PAZ | H5: DIA | I5: CBES | J5: TOTAL GANADO | K5: TOTAL DIA | L5: DIAS CBES | M5: TOTAL | N5: TOTAL (75%) | O5: OBSERVACION
C6: Empiezo | D6: Termino | F6: DE | G6: A
C7: 0 | D7: 0 | F7: 0 | G7: 0 | H7: =G7-F7+1 -> 1 | I7: =H7-3 -> -2 | J7: 0 | K7: =J7/30 -> 0 | M7: =K7*L7 -> 0 | N7: =M7*0.75 -> 0
A8: 1 | B8: MAMANI HUANCA ROSMARY MODESTA | C8: 45643 | D8: 45666 | E8: =+D8-C8+1 -> 24 | F8: 45658 | G8: 45666 | H8: =G8-F8+1 -> 9 | I8: =H8-3 -> 6 | J8: 8842 | K8: =J8/30 -> 294.73333 | L8: 9 | M8: =K8*L8 -> 2652.6 | N8: =M8*0.75 -> 1989.45
A9: 2 | B9: TOLIN TORDOYA FLORENCIO | E9: =+D9-C9+1 -> 1 | F9: 45679 | G9: 45687 | H9: =G9-F9+1 -> 9 | I9: =H9-3 -> 6 | J9: 7384 | K9: =J9/30 -> 246.13333 | L9: =+I9 -> 6 | M9: =K9*L9 -> 1476.8 | N9: =M9*0.75 -> 1107.6
E10: =+D10-C10+1 -> 1 | H10: =G10-F10+1 -> 1 | I10: =H10-3 -> -2 | K10: =J10/30 -> 0 | M10: =K10*L10 -> 0 | N10: =M10*0.75 -> 0
N11: =SUM(N7:N10) -> 3097.05
C12: BAJAS POR MATERNIDAD
A14: N° | B14: NOMBRE | C14: BAJA MEDICA | E14: DIA | F14: LA PAZ | H14: DIA | J14: TOTAL GANADO | K14: TOTAL DIA | L14: DIAS CBES | M14: TOTAL | N14: TOTAL (90%) | O14: OBSERVACION
C15: Empiezo | D15: Termino | F15: DE | G15: A
E16: =D16-C16+1 -> 1 | F16: 0 | G16: 0 | H16: =G16-F16+1 -> 1 | J16: 0 | K16: =J16/30 -> 0 | L16: 0 | M16: =K16*L16 -> 0 | N16: =M16*0.9 -> 0
A17: 1 | B17: MARCA MIRIAM | C17: 45630 | D17: 45719 | E17: =D17-C17+1 -> 90 | F17: 45658 | G17: 45687 | H17: =G17-F17+1 -> 30 | J17: 11619 | K17: =J17/30 -> 387.3 | L17: =+H17 -> 30 | M17: =K17*L17 -> 11619 | N17: =M17*0.9 -> 10457.1
E18: =D18-C18+1 -> 1 | F18: 0 | G18: 0 | H18: =G18-F18+1 -> 1 | J18: 0 | K18: =J18/30 -> 0 | L18: 0 | M18: =K18*L18 -> 0 | N18: =M18*0.9 -> 0
N19: =SUM(N16:N18) -> 10457.1
C20: ACCIDENTE DE TRABAJO
A22: N° | B22: NOMBRE | C22: BAJA MEDICA | F22: LA PAZ | H22: DIA | J22: TOTAL GANADO | K22: TOTAL DIA | L22: DIAS CBES | M22: TOTAL | N22: TOTAL (90%) | O22: OBSERVACION
C23: Empiezo | D23: Termino | F23: DE | G23: A
H24: =G24-F24+1 -> 1 | J24: 0 | K24: =J24/30 -> 0 | M24: =K24*L24 -> 0 | N24: =M24*0.9 -> 0
A25: 1 | H25: =G25-F25+1 -> 1 | K25: =J25/30 -> 0 | M25: =K25*L25 -> 0 | N25: =M25*0.9 -> 0
H26: =G26-F26+1 -> 1 | J26: 0 | K26: =J26/30 -> 0 | M26: =K26*L26 -> 0 | N26: =M26*0.9 -> 0
N27: =SUM(N24:N26) -> 0
K29: TOTAL REEMB | N29: =N11+N19+N27 -> 13554.15

Sheet MEDECIN
A1: MEDECIN S.R.L.
C2: ENFERMEDAD COMUN
A3: N° | B3: NOMBRE | C3: LA PAZ | E3: DIA | G3: CORRESPONDIENTE AL SIGUIENTE MES | I3: TOTAL GANADO | J3: TOTAL DIA | K3: DIAS CBES | L3: TOTAL | M3: TOTAL (75%) | N3: OBSERVACION
C4: DE | D4: A | G4: DE | H4: A
C5: 0 | D5: 0 | E5: =D5-C5+1 -> 1 | F5: =E5-3 -> -2 | I5: 0 | J5: =I5/30 -> 0 | L5: =J5*K5 -> 0 | M5: =L5*0.75 -> 0
A6: 1 | E6: =D6-C6+1 -> 1 | F6: =E6-3 -> -2 | G6: 45714 | H6: 45716 | I6: 8831.75 | J6: =I6/30 -> 294.39167 | L6: =J6*K6 -> 0 | M6: =L6*0.75 -> 0
C7: 0 | D7: 0 | E7: =D7-C7+1 -> 1 | F7: =E7-3 -> -2 | I7: 0 | J7: =I7/30 -> 0 | L7: =J7*K7 -> 0 | M7: =L7*0.75 -> 0
M8: =SUM(M5:M7) -> 0
C9: BAJAS POR MATERNIDAD
A11: N° | B11: NOMBRE | C11: LA PAZ | E11: DIA | G11: CORRESPONDIENTE AL SIGUIENTE MES | I11: TOTAL GANADO | J11: TOTAL DIA | K11: DIAS CBES | L11: TOTAL | M11: TOTAL (90%) | N11: OBSERVACION
C12: DE | D12: A | G12: DE | H12: A
C13: 0 | D13: 0 | E13: =D13-C13+1 -> 1 | G13: 0 | H13: 0 | I13: 0 | J13: =I13/30 -> 0 | L13: =J13*K13 -> 0 | M13: =L13*0.9 -> 0
E14: =D14-C14+1 -> 1 | I14: 0 | J14: =I14/30 -> 0 | L14: =J14*K14 -> 0 | M14: =L14*0.9 -> 0
E15: =D15-C15+1 -> 1 | I15: 0 | J15: =I15/30 -> 0 | L15: =J15*K15 -> 0 | M15: =L15*0.9 -> 0
M16: =SUM(M13:M15) -> 0
C17: ACCIDENTE DE TRABAJO
A19: N° | B19: NOMBRE | C19: LA PAZ | E19: DIA | G19: CORRESPONDIENTE AL SIGUIENTE MES | I19: TOTAL GANADO | J19: TOTAL DIA | K19: DIAS CBES | L19: TOTAL | M19: TOTAL (90%) | N19: OBSERVACION
C20: DE | D20: A | G20: DE | H20: A
E21: =D21-C21+1 -> 1 | I21: 0 | J21: =I21/30 -> 0 | K21: 0 | L21: =J21*K21 -> 0 | M21: =L21*0.9 -> 0
E22: =D22-C22+1 -> 1 | I22: 0 | J22: =I22/30 -> 0 | K22: 0 | L22: =J22*K22 -> 0 | M22: =L22*0.9 -> 0
E23: =D23-C23+1 -> 1 | I23: 0 | J23: =I23/30 -> 0 | K23: 0 | L23: =J23*K23 -> 0 | M23: =L23*0.9 -> 0
M24: =SUM(M21:M23) -> 0
J26: TOTAL REEMB | M26: =M8+M16+M24 -> 0

Sheet FOODEMSA
A1: FOODEMSA BOLIVIAN SRL
C2: ENFERMEDAD COMUN
A3: N° | B3: NOMBRE | C3: LA PAZ | E3: DIA | G3: CORRESPONDIENTE AL SIGUIENTE MES | I3: TOTAL GANADO | J3: TOTAL DIA | K3: DIAS CBES | L3: TOTAL | M3: TOTAL (75%) | N3: OBSERVACION
C4: DE | D4: A | G4: DE | H4: A
C5: 0 | D5: 0 | E5: =D5-C5+1 -> 1 | F5: =E5-3 -> -2 | I5: 0 | J5: =I5/30 -> 0 | L5: =J5*K5 -> 0 | M5: =L5*0.75 -> 0
A6: 1 | E6: =D6-C6+1 -> 1 | F6: =E6-3 -> -2 | J6: =I6/30 -> 0 | L6: =J6*K6 -> 0 | M6: =L6*0.75 -> 0
E7: =D7-C7+1 -> 1 | F7: =E7-3 -> -2 | J7: =I7/30 -> 0 | L7: =J7*K7 -> 0 | M7: =L7*0.75 -> 0
J8: =I8/30 -> 0 | L8: =J8*K8 -> 0 | M8: =L8*0.75 -> 0
M9: =SUM(M6:M7) -> 0
C10: BAJAS POR MATERNIDAD
A12: N° | B12: NOMBRE | C12: LA PAZ | E12: DIA | G12: CORRESPONDIENTE AL SIGUIENTE MES | I12: TOTAL GANADO | J12: TOTAL DIA | K12: DIAS CBES | L12: TOTAL | M12: TOTAL (90%) | N12: OBSERVACION
C13: DE | D13: A | G13: DE | H13: A
E14: =D14-C14+1 -> 1 | I14: 0 | J14: =I14/30 -> 0 | L14: =J14*K14 -> 0 | M14: =L14*0.9 -> 0
A15: 1 | E15: =D15-C15+1 -> 1 | F15: =+H15-G15+1 -> 1 | J15: =I15/30 -> 0 | L15: =J15*K15 -> 0 | M15: =L15*0.9 -> 0
E16: =D16-C16+1 -> 1 | I16: 0 | J16: =I16/30 -> 0 | L16: =J16*K16 -> 0 | M16: =L16*0.9 -> 0
M17: =SUM(M14:M16) -> 0
C18: ACCIDENTE DE TRABAJO
A20: N° | B20: NOMBRE | C20: LA PAZ | E20: DIA | G20: CORRESPONDIENTE AL SIGUIENTE MES | I20: TOTAL GANADO | J20: TOTAL DIA | K20: DIAS CBES | L20: TOTAL | M20: TOTAL (90%) | N20: OBSERVACION
C21: DE | D21: A | G21: DE | H21: A
I22: 0 | J22: =I22/30 -> 0 | L22: =J22*K22 -> 0 | M22: =L22*0.9 -> 0
E23: =D23-C23+1 -> 1 | J23: =I23/30 -> 0 | L23: =+J23*K23 -> 0 | M23: =L23*0.9 -> 0
E24: =D24-C24+1 -> 1 | J24: =I24/30 -> 0 | M24: =L24*0.9 -> 0
E25: =D25-C25+1 -> 1 | J25: =I25/30 -> 0 | M25: =L25*0.9 -> 0
M26: =SUM(M22:M25) -> 0
J28: TOTAL REEMB | M28: =M9+M17+M26 -> 0

Sheet EFITRUCKS
B1: CAJA BANCARIA ESTATAL DE SALUD
B2: COTIZACIONES | N2: NUMERO PATRONAL: | P2: 11-683-0001
A3: EFITRUCKS S.R.L.
C4: ENFERMEDAD COMUN
A5: N° | B5: NOMBRE | C5: LA PAZ | E5: DIA | G5: CORRESPONDIENTE AL SIGUIENTE MES | I5: DIA | K5: TOTAL GANADO | L5: TOTAL DIA | M5: DIAS CBES | N5: TOTAL | O5: TOTAL (75%) | P5: OBSERVACION
C6: DE | D6: A | G6: DE | H6: A
C7: 0 | D7: 0 | E7: =D7-C7+1 -> 1 | F7: =E7-3 -> -2 | I7: =H7-G7+1 -> 1 | J7: =I7-3 -> -2 | K7: 0 | L7: =K7/30 -> 0 | M7: 0 | N7: =L7*M7 -> 0 | O7: =N7*0.75 -> 0
A8: 1 | B8: SOLIZ HARB RUBEN JOSE | E8: =D8-C8+1 -> 1 | F8: =E8-3 -> -2 | G8: 45475 | H8: 45488 | I8: =H8-G8+1 -> 14 | J8: =I8-3 -> 11 | K8: 4590 | L8: =K8/30 -> 153 | N8: =L8*M8 -> 0 | O8: =N8*0.75 -> 0
E9: =D9-C9+1 -> 1 | F9: =E9-3 -> -2 | I9: =H9-G9+1 -> 1 | J9: =I9-3 -> -2 | K9: 0 | L9: =K9/30 -> 0 | N9: =L9*M9 -> 0 | O9: =N9*0.75 -> 0
O10: =SUM(O7:O9) -> 0
C11: BAJAS POR MATERNIDAD
A13: N° | B13: NOMBRE | C13: LA PAZ | E13: DIA | G13: CORRESPONDIENTE AL SIGUIENTE MES | I13: DIA | K13: TOTAL GANADO | L13: TOTAL DIA | M13: DIAS CBES | N13: TOTAL | O13: TOTAL (90%) | P13: OBSERVACION
C14: DE | D14: A | G14: DE | H14: A
E15: =D15-C15+1 -> 1 | I15: =H15-G15+1 -> 1 | K15: 0 | L15: =K15/30 -> 0 | N15: =L15*M15 -> 0 | O15: =N15*0.9 -> 0
A16: 1 | E16: =D16-C16+1 -> 1 | I16: =H16-G16+1 -> 1 | L16: =K16/30 -> 0 | N16: =L16*M16 -> 0 | O16: =N16*0.9 -> 0
E17: =D17-C17+1 -> 1 | I17: =H17-G17+1 -> 1 | K17: 0 | L17: =K17/30 -> 0 | N17: =L17*M17 -> 0 | O17: =N17*0.9 -> 0
O18: =SUM(O15:O17) -> 0
C19: ACCIDENTE DE TRABAJO
A21: N° | B21: NOMBRE | C21: LA PAZ | E21: DIA | G21: CORRESPONDIENTE AL SIGUIENTE MES | I21: DIA | K21: TOTAL GANADO | L21: TOTAL DIA | M21: DIAS CBES | N21: TOTAL | O21: TOTAL (90%) | P21: OBSERVACION
C22: DE | D22: A | G22: DE | H22: A
E23: =D23-C23+1 -> 1 | I23: =H23-G23+1 -> 1 | K23: 0 | L23: =K23/30 -> 0 | M23: 0 | N23: =L23*M23 -> 0 | O23: =N23*0.9 -> 0
E24: =D24-C24+1 -> 1 | I24: =H24-G24+1 -> 1 | K24: 0 | L24: =K24/30 -> 0 | M24: 0 | N24: =L24*M24 -> 0 | O24: =N24*0.9 -> 0
E25: =D25-C25+1 -> 1 | I25: =H25-G25+1 -> 1 | K25: 0 | L25: =K25/30 -> 0 | M25: 0 | N25: =L25*M25 -> 0 | O25: =N25*0.9 -> 0
O26: =SUM(O23:O25) -> 0
L28: TOTAL REEMB | O28: =O26+O18+O10 -> 0

Sheet CONSULADO
A1: CONSULADO GENERAL DEL PERU
C2: ENFERMEDAD COMUN
A3: N° | B3: NOMBRE | C3: BAJA MEDICA | F3: Correspondiente al mes | H3: DIA | J3: TOTAL GANADO | K3: TOTAL DIA | L3: DIAS CBES | M3: TOTAL | N3: TOTAL (75%) | O3: OBSERVACION
C4: Empiezo | D4: Termino | F4: DE | G4: A
F5: 0 | G5: 0 | H5: =G5-F5+1 -> 1 | I5: =H5-3 -> -2 | J5: 0 | K5: =J5/30 -> 0 | M5: =K5*L5 -> 0 | N5: =M5*0.75 -> 0
A6: 1 | E6: =D6-C6+1 -> 1 | H6: =G6-F6+1 -> 1 | I6: =H6-3 -> -2 | K6: =J6/30 -> 0 | M6: =K6*L6 -> 0 | N6: =M6*0.75 -> 0
H7: =G7-F7+1 -> 1 | I7: =H7-3 -> -2 | J7: 0 | K7: =J7/30 -> 0 | M7: =K7*L7 -> 0 | N7: =M7*0.75 -> 0
N8: =SUM(N5:N7) -> 0
C9: BAJAS POR MATERNIDAD
A11: N° | B11: NOMBRE | C11: BAJA MEDICA | F11: Correspondiente al mes | H11: DIA | J11: TOTAL GANADO | K11: TOTAL DIA | L11: DIAS CBES | M11: TOTAL | N11: TOTAL (90%) | O11: OBSERVACION
C12: Empiezo | D12: Termino | F12: DE | G12: A
C13: 0 | D13: 0 | E13: =D13-C13+1 -> 1 | F13: 0 | G13: 0 | H13: =G13-F13+1 -> 1 | J13: 0 | K13: =J13/30 -> 0 | L13: 0 | M13: =K13*L13 -> 0 | N13: =M13*0.9 -> 0
C15: 0 | D15: 0 | E15: =D15-C15+1 -> 1 | F15: 0 | G15: 0 | H15: =G15-F15+1 -> 1 | J15: 0 | K15: =J15/30 -> 0 | L15: 0 | M15: =K15*L15 -> 0 | N15: =M15*0.9 -> 0
N16: =SUM(N13:N15) -> 0
C17: ACCIDENTE DE TRABAJO
A19: N° | B19: NOMBRE | C19: BAJA MEDICA | F19: Correspondiente al mes | J19: TOTAL GANADO | K19: TOTAL DIA | L19: DIAS CBES | M19: TOTAL | N19: TOTAL (90%) | O19: OBSERVACION
C20: Empiezo | D20: Termino | F20: DE | G20: A
C21: 0 | D21: 0 | F21: 0 | G21: 0 | H21: =G21-F21+1 -> 1 | J21: 0 | K21: =J21/30 -> 0 | M21: =K21*L21 -> 0 | N21: =M21*0.9 -> 0
F22: 0 | G22: 0 | H22: =G22-F22+1 -> 1 | J22: 0 | K22: =J22/30 -> 0 | M22: =K22*L22 -> 0 | N22: =M22*0.9 -> 0
F23: 0 | G23: 0 | H23: =G23-F23+1 -> 1 | J23: 0 | K23: =J23/30 -> 0 | M23: =K23*L23 -> 0 | N23: =M23*0.9 -> 0
N24: =SUM(N21:N23) -> 0
K26: TOTAL REEMB | N26: =N24+N16+N8 -> 0

Sheet FOIANINI
A1: CAJA BANCARIA ESTATAL DE SALUD | M1: Nº PATRONAL:
B2: COTIZACIONES | M2: R.A. ASUSS: | O2: 0362/2024
A3: CLINICA FOIANINI
C4: ENFERMEDAD COMUN
A5: N° | B5: NOMBRE | C5: BAJA MEDICA | F5: Correspondiente al mes | H5: DIA | J5: TOTAL GANADO | K5: TOTAL DIA | L5: DIAS CBES | M5: TOTAL | N5: TOTAL (75%) | O5: OBSERVACION
C6: Empiezo | D6: Termino | F6: DE | G6: A
F7: 0 | G7: 0 | H7: =G7-F7+1 -> 1 | I7: =H7-3 -> -2 | J7: 0 | K7: =J7/30 -> 0 | M7: =K7*L7 -> 0 | N7: =M7*0.75 -> 0
A8: 1 | B8: MONTAÑO PLATA LENY | C8: 45652 | D8: 45658 | E8: =D8-C8+1 -> 7 | F8: 45658 | G8: 45658 | H8: =G8-F8+1 -> 1 | I8: =H8-3 -> -2 | J8: 4420.98 | K8: =J8/30 -> 147.366 | L8: 1 | M8: =K8*L8 -> 147.366 | N8: =M8*0.75 -> 110.5245
A9: 2 | B9: MONTAÑO PLATA LENY | E9: =D9-C9+1 -> 1 | F9: 45671 | G9: 45686 | H9: =G9-F9+1 -> 16 | I9: =H9-3 -> 13 | J9: 4094.06 | K9: =J9/30 -> 136.46867 | L9: =+I9 -> 13 | M9: =K9*L9 -> 1774.0927 | N9: =M9*0.75 -> 1330.5695
H10: =G10-F10+1 -> 1 | I10: =H10-3 -> -2 | K10: =J10/30 -> 0 | M10: =K10*L10 -> 0 | N10: =M10*0.75 -> 0
N11: =SUM(N7:N10) -> 1441.094
C12: BAJAS POR MATERNIDAD
A14: N° | B14: NOMBRE | C14: BAJA MEDICA | F14: Correspondiente al mes | H14: DIA | J14: TOTAL GANADO | K14: TOTAL DIA | L14: DIAS CBES | M14: TOTAL | N14: TOTAL (90%) | O14: OBSERVACION
C15: Empiezo | D15: Termino | F15: DE | G15: A
C16: 0 | D16: 0 | E16: =D16-C16+1 -> 1 | F16: 0 | G16: 0 | H16: =G16-F16+1 -> 1 | J16: 0 | K16: =J16/30 -> 0 | L16: 0 | M16: =K16*L16 -> 0 | N16: =M16*0.9 -> 0
A17: 1 | E17: =D17-C17+1 -> 1 | F17: 45017 | G17: 45046 | H17: =G17-F17+1 -> 30 | K17: =J17/30 -> 0 | M17: =K17*L17 -> 0 | N17: =M17*0.9 -> 0
A18: 2 | E18: =D18-C18+1 -> 1 | H18: =G18-F18+1 -> 1 | K18: =J18/30 -> 0 | M18: =K18*L18 -> 0 | N18: =M18*0.9 -> 0
N19: =SUM(N16:N18) -> 0
C20: ACCIDENTE DE TRABAJO
A22: N° | B22: NOMBRE | C22: BAJA MEDICA | F22: Correspondiente al mes | J22: TOTAL GANADO | K22: TOTAL DIA | L22: DIAS CBES | M22: TOTAL | N22: TOTAL (90%) | O22: OBSERVACION
C23: Empiezo | D23: Termino | F23: DE | G23: A
C24: 0 | D24: 0 | F24: 0 | G24: 0 | H24: =G24-F24+1 -> 1 | J24: 0 | K24: =J24/30 -> 0 | M24: =K24*L24 -> 0 | N24: =M24*0.9 -> 0
H25: =G25-F25+1 -> 1 | J25: 0 | K25: =J25/30 -> 0 | M25: =K25*L25 -> 0 | N25: =M25*0.9 -> 0
H26: =G26-F26+1 -> 1 | J26: 0 | K26: =J26/30 -> 0 | M26: =K26*L26 -> 0 | N26: =M26*0.9 -> 0
N27: =SUM(N24:N26) -> 0
K29: TOTAL REEMB | N29: =N27+N19+N11 -> 1441.094

Sheet ONEDATA
A1: CAJA BANCARIA ESTATAL DE SALUD | M1: Nº1 PATRONAL: | O1: 11-927-0014
A2: COTIZACIONES
A3: ONEDATA SOPORTE INTEGRAL SRL
C4: ENFERMEDAD COMUN
A5: N° | B5: NOMBRE | C5: BAJA MEDICA | F5: Correspondiente al mes | H5: DIA | J5: TOTAL GANADO | K5: TOTAL DIA | L5: DIAS CBES | M5: TOTAL | N5: TOTAL (75%) | O5: OBSERVACION
C6: Empiezo | D6: Termino | F6: DE | G6: A
F7: 0 | G7: 0 | H7: =G7-F7+1 -> 1 | I7: =H7-3 -> -2 | J7: 0 | K7: =J7/30 -> 0 | M7: =K7*L7 -> 0 | N7: =M7*0.75 -> 0
A8: 1 | B8: TORO GUARACHI MIGUEL AMERICO | E8: =D8-C8+1 -> 1 | F8: 45665 | G8: 45671 | H8: =G8-F8+1 -> 7 | I8: =H8-3 -> 4 | J8: 2500 | K8: =J8/30 -> 83.333333 | L8: =+I8 -> 4 | M8: =K8*L8 -> 333.33333 | N8: =M8*0.75 -> 250
E9: =D9-C9+1 -> 1 | H9: =G9-F9+1 -> 1 | I9: =H9-3 -> -2 | K9: =J9/30 -> 0 | L9: 0 | M9: =K9*L9 -> 0 | N9: =M9*0.75 -> 0
N10: =SUM(N7:N9) -> 250
C11: BAJAS POR MATERNIDAD
A13: N° | B13: NOMBRE | C13: BAJA MEDICA | F13: Correspondiente al mes | H13: DIA | J13: TOTAL GANADO | K13: TOTAL DIA | L13: DIAS CBES | M13: TOTAL | N13: TOTAL (90%) | O13: OBSERVACION
C14: Empiezo | D14: Termino | F14: DE | G14: A
C15: 0 | D15: 0 | E15: =D15-C15+1 -> 1 | F15: 0 | G15: 0 | H15: =G15-F15+1 -> 1 | J15: 0 | K15: =J15/30 -> 0 | L15: 0 | M15: =K15*L15 -> 0 | N15: =M15*0.9 -> 0
E16: =D16-C16+1 -> 1 | H16: =G16-F16+1 -> 1 | K16: =J16/30 -> 0 | M16: =K16*L16 -> 0 | N16: =M16*0.9 -> 0
E17: =D17-C17+1 -> 1 | H17: =G17-F17+1 -> 1 | K17: =J17/30 -> 0 | M17: =K17*L17 -> 0 | N17: =M17*0.9 -> 0
N18: =SUM(N15:N17) -> 0
C19: ACCIDENTE DE TRABAJO
A21: N° | B21: NOMBRE | C21: BAJA MEDICA | F21: Correspondiente al mes | J21: TOTAL GANADO | K21: TOTAL DIA | L21: DIAS CBES | M21: TOTAL | N21: TOTAL (90%) | O21: OBSERVACION
C22: Empiezo | D22: Termino | F22: DE | G22: A
C23: 0 | D23: 0 | F23: 0 | G23: 0 | H23: =G23-F23+1 -> 1 | J23: 0 | K23: =J23/30 -> 0 | M23: =K23*L23 -> 0 | N23: =M23*0.9 -> 0
H24: =G24-F24+1 -> 1 | J24: 0 | K24: =J24/30 -> 0 | M24: =K24*L24 -> 0 | N24: =M24*0.9 -> 0
H25: =G25-F25+1 -> 1 | J25: 0 | K25: =J25/30 -> 0 | M25: =K25*L25 -> 0 | N25: =M25*0.9 -> 0
N26: =SUM(N23:N25) -> 0
K28: TOTAL REEMB | N28: =N26+N18+N10 -> 250

Sheet OPERADORALATIV
B1: CAJA BANCARIA ESTATAL DE SALUD | M1: R.A. Nº | N1: 347/2024 | O1: ASUSS
B2: COTIZACIONES
A3: OPERADORALATIV ADMINISTRACION S.A.
C4: ENFERMEDAD COMUN
A5: N° | B5: NOMBRE | C5: BAJA MEDICA | F5: Correspondiente al mes | H5: DIA | J5: TOTAL GANADO | K5: TOTAL DIA | L5: DIAS CBES | M5: TOTAL | N5: TOTAL (75%) | O5: OBSERVACION
C6: Empiezo | D6: Termino | F6: DE | G6: A
F7: 0 | G7: 0 | H7: =G7-F7+1 -> 1 | I7: =H7-3 -> -2 | J7: 0 | K7: =J7/30 -> 0 | M7: =K7*L7 -> 0 | N7: =M7*0.75 -> 0
A8: 1 | E8: =D8-C8+1 -> 1 | H8: =G8-F8+1 -> 1 | I8: =H8-3 -> -2 | K8: =J8/30 -> 0 | M8: =K8*L8 -> 0 | N8: =M8*0.75 -> 0
E9: =D9-C9+1 -> 1 | H9: =G9-F9+1 -> 1 | I9: =H9-3 -> -2 | K9: =J9/30 -> 0 | M9: =K9*L9 -> 0 | N9: =M9*0.75 -> 0
N10: =SUM(N7:N9) -> 0
C11: BAJAS POR MATERNIDAD
A13: N° | B13: NOMBRE | C13: BAJA MEDICA | F13: Correspondiente al mes | H13: DIA | J13: TOTAL GANADO | K13: TOTAL DIA | L13: DIAS CBES | M13: TOTAL | N13: TOTAL (90%) | O13: OBSERVACION
C14: Empiezo | D14: Termino | F14: DE | G14: A
C15: 0 | D15: 0 | E15: =D15-C15+1 -> 1 | F15: 0 | G15: 0 | H15: =G15-F15+1 -> 1 | J15: 0 | K15: =J15/30 -> 0 | L15: 0 | M15: =K15*L15 -> 0 | N15: =M15*0.9 -> 0
A16: 1 | D16: 45654 | E16: =D16-C16+1 -> 45655 | H16: =G16-F16+1 -> 1 | K16: =J16/30 -> 0 | L16: 0 | M16: =K16*L16 -> 0 | N16: =M16*0.9 -> 0
N17: =SUM(N15:N16) -> 0
C18: ACCIDENTE DE TRABAJO
A20: N° | B20: NOMBRE | C20: BAJA MEDICA | F20: Correspondiente al mes | J20: TOTAL GANADO | K20: TOTAL DIA | L20: DIAS CBES | M20: TOTAL | N20: TOTAL (90%) | O20: OBSERVACION
C21: Empiezo | D21: Termino | F21: DE | G21: A
C22: 0 | D22: 0 | F22: 0 | G22: 0 | H22: =G22-F22+1 -> 1 | J22: 0 | K22: =J22/30 -> 0 | M22: =K22*L22 -> 0 | N22: =M22*0.9 -> 0
H23: =G23-F23+1 -> 1 | J23: 0 | K23: =J23/30 -> 0 | M23: =K23*L23 -> 0 | N23: =M23*0.9 -> 0
H24: =G24-F24+1 -> 1 | J24: 0 | K24: =J24/30 -> 0 | M24: =K24*L24 -> 0 | N24: =M24*0.9 -> 0
N25: =SUM(N22:N24) -> 0
K27: TOTAL REEMB | N27: =N25+N17+N10 -> 0

Sheet COSAIN
A1: CAJA BANCARIA ESTATAL DE SALUD | N1: NUMERO PATRONAL: | P1: 21-923-0002
A2: COTIZACIONES
A3: COSAIN
C4: ENFERMEDAD COMUN
A5: N° | B5: NOMBRE | C5: LA PAZ | E5: DIA | F5: CBES | G5: CORRESPONDIENTE AL SIGUIENTE MES | I5: TOTAL GANADO | J5: DIA | K5: CBES | L5: TOTAL DIA | M5: DIAS CBES | N5: TOTAL | O5: TOTAL (75%) | P5: OBSERVACION
C6: DE | D6: A | G6: DE | H6: A
C7: 0 | D7: 0 | E7: =D7-C7+1 -> 1 | F7: =E7-3 -> -2 | I7: 0 | J7: =I7-H7+1 -> 1 | K7: =J7-3 -> -2 | L7: =I7/30 -> 0 | N7: =L7*M7 -> 0 | O7: =N7*0.75 -> 0
A8: 1 | B8: VILLARROEL CARRASCO LENNY | C8: 45656 | D8: 45676 | E8: =D8-C8+1 -> 21 | F8: =E8-3 -> 18 | G8: 45658 | H8: 45676 | I8: 3552.25 | J8: =+H8-G8+1 -> 19 | K8: =J8-3 -> 16 | L8: =I8/30 -> 118.40833 | M8: 17 | N8: =L8*M8 -> 2012.9417 | O8: =N8*0.75 -> 1509.7062
A9: 2 | B9: SARAVIA FERRUFINO ANGELICA | E9: =D9-C9+1 -> 1 | F9: =E9-3 -> -2 | G9: 45666 | H9: 45675 | I9: 2875 | J9: =+H9-G9+1 -> 10 | K9: =J9-3 -> 7 | L9: =I9/30 -> 95.833333 | M9: =+K9 -> 7 | N9: =L9*M9 -> 670.83333 | O9: =N9*0.75 -> 503.125
E10: =D10-C10+1 -> 1 | F10: =E10-3 -> -2 | J10: =+H10-G10+1 -> 1 | K10: =J10-3 -> -2 | L10: =I10/30 -> 0 | N10: =L10*M10 -> 0 | O10: =N10*0.75 -> 0
O11: =SUM(O7:O10) -> 2012.8312
C12: BAJAS POR MATERNIDAD
A14: N° | B14: NOMBRE | C14: LA PAZ | E14: DIA | G14: CORRESPONDIENTE AL SIGUIENTE MES | I14: TOTAL GANADO | L14: TOTAL DIA | M14: DIAS CBES | N14: TOTAL | O14: TOTAL (90%) | P14: OBSERVACION
C15: DE | D15: A | G15: DE | H15: A
E16: =D16-C16+1 -> 1 | I16: 0 | L16: =I16/30 -> 0 | N16: =L16*M16 -> 0 | O16: =N16*0.9 -> 0
A17: 1 | B17: PINTO RIOS CYNTIA ROXANA | C17: 45624 | D17: 45713 | E17: =D17-C17+1 -> 90 | F17: =H17-G17+1 -> 30 | G17: 45658 | H17: 45687 | I17: 5745.91 | J17: =+H17-G17+1 -> 30 | L17: =I17/30 -> 191.53033 | M17: =+J17 -> 30 | N17: =L17*M17 -> 5745.91 | O17: =N17*0.9 -> 5171.319
E18: =D18-C18+1 -> 1 | F18: =H18-G18+1 -> 1 | J18: =+H18-G18+1 -> 1 | L18: =I18/30 -> 0 | N18: =L18*M18 -> 0 | O18: =N18*0.9 -> 0
O19: =SUM(O16:O18) -> 5171.319
C20: ACCIDENTE DE TRABAJO
A22: N° | B22: NOMBRE | C22: LA PAZ | E22: DIA | G22: CORRESPONDIENTE AL SIGUIENTE MES | I22: TOTAL GANADO | L22: TOTAL DIA | M22: DIAS CBES | N22: TOTAL | O22: TOTAL (90%) | P22: OBSERVACION
C23: DE | D23: A | G23: DE | H23: A
C24: 0 | D24: 0 | E24: =D24-C24+1 -> 1 | I24: 0 | L24: =I24/30 -> 0 | M24: 0 | N24: =L24*M24 -> 0 | O24: =N24*0.9 -> 0
E25: =D25-C25+1 -> 1 | I25: 0 | L25: =I25/30 -> 0 | M25: 0 | N25: =L25*M25 -> 0 | O25: =N25*0.9 -> 0
E26: =D26-C26+1 -> 1 | I26: 0 | L26: =I26/30 -> 0 | M26: 0 | N26: =L26*M26 -> 0 | O26: =N26*0.9 -> 0
O27: =SUM(O24:O26) -> 0
L29: TOTAL REEMB | O29: =O11+O19+O27 -> 7184.1503

Sheet FOLCOL
A1: CAJA BANCARIA ESTATAL DE SALUD | M1: Nº PATRONAL: | O1: 61-011-0001
B2: COTIZACIONES
A3: FOLCOL BOLIVIA
C4: ENFERMEDAD COMUN
A5: N° | B5: NOMBRE | C5: BAJA MEDICA | F5: LA PAZ | H5: DIA | I5: CBES | J5: TOTAL GANADO | K5: TOTAL DIA | L5: DIAS CBES | M5: TOTAL | N5: TOTAL (75%) | O5: OBSERVACION
C6: Empiezo | D6: Termino | F6: DE | G6: A
C7: 0 | D7: 0 | F7: 0 | G7: 0 | H7: =G7-F7+1 -> 1 | I7: =H7-3 -> -2 | J7: 0 | K7: =J7/30 -> 0 | M7: =K7*L7 -> 0 | N7: =M7*0.75 -> 0
A8: 1 | B8: AGUILERA CAMPOS KATIA | C8: 45607 | D8: 45642 | E8: =+D8-C8+1 -> 36 | F8: 45627 | G8: 45642 | H8: =G8-F8+1 -> 16 | I8: =H8-3 -> 13 | J8: 10753.2 | K8: =J8/30 -> 358.44 | M8: =K8*L8 -> 0 | N8: =M8*0.75 -> 0
H9: =G9-F9+1 -> 1 | I9: =H9-3 -> -2 | K9: =J9/30 -> 0 | M9: =K9*L9 -> 0 | N9: =M9*0.75 -> 0
N10: =SUM(N7:N9) -> 0
C11: BAJAS POR MATERNIDAD
A13: N° | B13: NOMBRE | C13: BAJA MEDICA | E13: DIA | F13: LA PAZ | H13: DIA | J13: TOTAL GANADO | K13: TOTAL DIA | L13: DIAS CBES | M13: TOTAL | N13: TOTAL (90%) | O13: OBSERVACION
